Workbook

Sheet MRP
A1: COD SAP | B1: CodInternoArti | C1: DescripcionArti | D1: Nivel_Integracion_3 | E1: Nivel_Integracion_4 | F1: Nivel_Integracion_5 | G1: Ubicacion | H1: 52 | I1: 53 | J1: 1 | K1: 2 | L1: 55 | M1: 56 | N1: TOTAL | O1: STK CIU | P1: STK MOR | Q1: STK MOR3 | R1: STATUS | S1: DIFERENCIA | T1: sem 1+2 | U1: CATEGORY | V1: ESTA CONTEMPLADO? | W1: EAN CORREGIDO
A2: 2006407 | B2: 16204006A | C2: ROLLO BOLSA ARRANQUE 60 x 90 | D2: BOLSAS | E2: BOLSAS ARRANQUE | F2: BOLSAS ARRANQUE | G2: Ciudadela | H2: 25 | I2: 11 | J2: 18 | K2: 5 | L2: 18 | M2: 9 | N2: 111.8 | O2: 0 | P2: 0 | Q2: 0 | R2: COMPRAR | S2: 111.8 | T2: -36 | U2: GASTON VECCHIO | V2: =_xlfn.XMATCH(Tabla4[[#This Row],[EAN CORREGIDO]],'Calcular necesidad'!L:L) -> 5 | W2: =TRIM(Tabla4[[#This Row],[CodInternoArti]]) -> 16204006A
A3: 2006442 | B3: 13044000A | C3: RESINITE (FILM DE PVC) x ROLLO | D3: VARIOS | E3: RESINITE | F3: RESINITE PVC | G3: Ciudadela | H3: 53 | I3: 35 | J3: 48 | K3: 47 | L3: 46 | M3: 35 | N3: 343.2 | O3: 0 | P3: 0 | Q3: 0 | R3: COMPRAR | S3: 343.2 | T3: -88 | U3: GASTON VECCHIO | V3: =_xlfn.XMATCH(Tabla4[[#This Row],[EAN CORREGIDO]],'Calcular necesidad'!L:L) -> 2 | W3: =TRIM(Tabla4[[#This Row],[CodInternoArti]]) -> 13044000A
A4: 2006265 | B4: 14004000A | C4: BARBIJOS x 25 UNID | D4: VARIOS | E4: BARBIJO DESCARTABLE | F4: BARBIJO DESCARTABLE | G4: Ciudadela | H4: 13 | I4: 2 | J4: 20 | L4: 12 | M4: 2 | N4: 63.7 | O4: 0 | P4: 0 | Q4: 0 | R4: COMPRAR | S4: 63.7 | T4: -15 | U4: GASTON VECCHIO | V4: =_xlfn.XMATCH(Tabla4[[#This Row],[EAN CORREGIDO]],'Calcular necesidad'!L:L) -> 11 | W4: =TRIM(Tabla4[[#This Row],[CodInternoArti]]) -> 14004000A
A5: 2006406 | B5: 16204003A | C5: ROLLO BOLSA ARRANQUE 40 x 60 | D5: BOLSAS | E5: BOLSAS ARRANQUE | F5: BOLSAS ARRANQUE | G5: Ciudadela | H5: 14 | I5: 11 | J5: 15 | K5: 29 | L5: 14 | M5: 11 | N5: 122.2 | O5: 0 | P5: 0 | Q5: 0 | R5: COMPRAR | S5: 122.2 | T5: -25 | U5: GASTON VECCHIO | V5: =_xlfn.XMATCH(Tabla4[[#This Row],[EAN CORREGIDO]],'Calcular necesidad'!L:L) -> 9 | W5: =TRIM(Tabla4[[#This Row],[CodInternoArti]]) -> 16204003A
A6: 2006408 | B6: 16208001A | C6: ROLLO DE BOLSA DE ARRANQUE 20 x 30 | D6: BOLSAS | E6: BOLSAS ARRANQUE | F6: BOLSAS ARRANQUE | G6: Ciudadela | H6: 27 | I6: 18 | J6: 16 | K6: 23 | L6: 18 | M6: 18 | N6: 156 | O6: 0 | P6: 0 | Q6: 0 | R6: COMPRAR | S6: 156 | T6: -45 | U6: GASTON VECCHIO | V6: =_xlfn.XMATCH(Tabla4[[#This Row],[EAN CORREGIDO]],'Calcular necesidad'!L:L) -> 7 | W6: =TRIM(Tabla4[[#This Row],[CodInternoArti]]) -> 16208001A
A7: 2006353 | B7: 17030001A | C7: GUANTE DE LATEX x 100 UNID | D7: VARIOS | E7: DESCARTABLES | F7: GUANTE LATEX | G7: Ciudadela | H7: 64 | I7: 77 | J7: 86 | K7: 95 | L7: 92 | M7: 79 | N7: 640.9 | O7: 0 | P7: 0 | Q7: 0 | R7: COMPRAR | S7: 640.9 | T7: -141 | U7: GASTON VECCHIO | V7: =_xlfn.XMATCH(Tabla4[[#This Row],[EAN CORREGIDO]],'Calcular necesidad'!L:L) -> 8 | W7: =TRIM(Tabla4[[#This Row],[CodInternoArti]]) -> 17030001A
A8: 2006151 | B8: 13069000A | C8: AGITADOR x 1000 U | D8: DESCARTABLES | E8: DESCARTABLES | F8: AGITADOR | G8: Ciudadela | H8: 9 | I8: 12 | J8: 14 | K8: 12 | L8: 6 | M8: 6 | N8: 76.7 | O8: 0 | P8: 0 | Q8: 0 | R8: COMPRAR | S8: 76.7 | T8: -21 | U8: GASTON VECCHIO | V8: =_xlfn.XMATCH(Tabla4[[#This Row],[EAN CORREGIDO]],'Calcular necesidad'!L:L) -> 4 | W8: =TRIM(Tabla4[[#This Row],[CodInternoArti]]) -> 13069000A
A9: 2006657 | B9: 13072000A | C9: FOLEX 20CMX25XCM XKG | D9: PAPEL | E9: PAPEL FOLEX | F9: PAPEL FOLEX | G9: Ciudadela | I9: 2 | J9: 1 | K9: 2 | L9: 1 | M9: 2 | N9: 10.4 | O9: 0 | P9: 0 | Q9: 0 | R9: COMPRAR | S9: 10.4 | T9: -2 | U9: GASTON VECCHIO | V9: =_xlfn.XMATCH(Tabla4[[#This Row],[EAN CORREGIDO]],'Calcular necesidad'!L:L) -> 10 | W9: =TRIM(Tabla4[[#This Row],[CodInternoArti]]) -> 13072000A
A10: 2006461 | B10: 14047013A | C10: SERVILLE BCA 30X30X1000U S/LOGO | D10: SERVILLETAS DESC | E10: SERVILLETAS DESC S/LOGO | F10: SERVILLETA DESC S/LOGO | G10: Ciudadela | H10: 3 | I10: 4 | J10: 3 | K10: 4 | L10: 3 | M10: 4 | N10: 27.3 | O10: 0 | P10: 0 | Q10: 0 | R10: COMPRAR | S10: 27.3 | T10: -7 | U10: GASTON VECCHIO | V10: =_xlfn.XMATCH(Tabla4[[#This Row],[EAN CORREGIDO]],'Calcular necesidad'!L:L) -> 17 | W10: =TRIM(Tabla4[[#This Row],[CodInternoArti]]) -> 14047013A
A11: 2006486 | B11: 16204004A | C11: ROLLO BOLSA ARRANQUE 45 x 60 | D11: BOLSAS | E11: BOLSAS ARRANQUE | F11: BOLSAS ARRANQUE | G11: Ciudadela | H11: 10 | I11: 8 | J11: 4 | K11: 4 | L11: 4 | M11: 4 | N11: 44.2 | O11: 0 | P11: 0 | Q11: 0 | R11: COMPRAR | S11: 44.2 | T11: -18 | U11: GASTON VECCHIO | V11: =_xlfn.XMATCH(Tabla4[[#This Row],[EAN CORREGIDO]],'Calcular necesidad'!L:L) -> 6 | W11: =TRIM(Tabla4[[#This Row],[CodInternoArti]]) -> 16204004A
A12: 2006779 | B12: 17018002A | C12: COFIAS DESCARTABLES X 100 | D12: VARIOS | E12: DESCARTABLES | F12: COFIA DESCARTABLE | G12: Ciudadela | H12: 38 | I12: 32 | J12: 38 | K12: 36 | L12: 34 | M12: 32 | N12: 273 | O12: 0 | P12: 0 | Q12: 0 | R12: COMPRAR | S12: 273 | T12: -70 | U12: GASTON VECCHIO | V12: =_xlfn.XMATCH(Tabla4[[#This Row],[EAN CORREGIDO]],'Calcular necesidad'!L:L) -> 16 | W12: =TRIM(Tabla4[[#This Row],[CodInternoArti]]) -> 17018002A
A13: 2006234 | B13: 16204005A | C13: ROLLO BOLSA ARRANQUE 25X35 | D13: BOLSAS | E13: BOLSAS ARRANQUE | F13: BOLSAS ARRANQUE | G13: Ciudadela | H13: 14 | I13: 18 | J13: 23 | K13: 5 | L13: 15 | M13: 15 | N13: 117 | O13: 0 | P13: 0 | Q13: 0 | R13: COMPRAR | S13: 117 | T13: -32 | U13: GASTON VECCHIO | V13: =_xlfn.XMATCH(Tabla4[[#This Row],[EAN CORREGIDO]],'Calcular necesidad'!L:L) -> 12 | W13: =TRIM(Tabla4[[#This Row],[CodInternoArti]]) -> 16204005A
A14: 2006671 | B14: 16032005A | C14: CAJA P/PIZZA GRANDE x U | D14: CAJAS | E14: CAJAS CARTON | F14: CAJA P/ PIZZA | G14: Ciudadela | H14: 25 | J14: 25 | K14: 10 | L14: 25 | N14: 110.5 | O14: 0 | P14: 0 | Q14: 0 | R14: COMPRAR | S14: 110.5 | T14: -25 | U14: GASTON VECCHIO | V14: =_xlfn.XMATCH(Tabla4[[#This Row],[EAN CORREGIDO]],'Calcular necesidad'!L:L) -> 14 | W14: =TRIM(Tabla4[[#This Row],[CodInternoArti]]) -> 16032005A
A15: 2006404 | B15: 14047015A | C15: SERVILLETA BCA 33X33X1000U GL | D15: SERVILLETAS DESC | E15: SERVILLETAS DESC C/LOGO | F15: SERVILLETA DESC C/LOGO | G15: Ciudadela | J15: 4 | N15: 5.2 | O15: 0 | P15: 0 | Q15: 0 | R15: COMPRAR | S15: 5.2 | T15: 0 | U15: GASTON VECCHIO | V15: =_xlfn.XMATCH(Tabla4[[#This Row],[EAN CORREGIDO]],'Calcular necesidad'!L:L) -> 19 | W15: =TRIM(Tabla4[[#This Row],[CodInternoArti]]) -> 14047015A
A16: 2006487 | B16: 16204014A | C16: ROLLO BOLSA ARRANQUE 15x20 | D16: BOLSAS | E16: BOLSAS ARRANQUE | F16: BOLSAS ARRANQUE | G16: Ciudadela | H16: 32 | I16: 41 | J16: 41 | K16: 51 | L16: 26 | M16: 41 | N16: 301.6 | O16: 0 | P16: 0 | Q16: 0 | R16: COMPRAR | S16: 301.6 | T16: -73 | U16: GASTON VECCHIO | V16: =_xlfn.XMATCH(Tabla4[[#This Row],[EAN CORREGIDO]],'Calcular necesidad'!L:L) -> 23 | W16: =TRIM(Tabla4[[#This Row],[CodInternoArti]]) -> 16204014A
A17: 2006800 | B17: 14047000A | C17: SERVILLE BCA 33X32X1000U S/LOGO | D17: SERVILLETAS DESC | E17: SERVILLETAS DESC S/LOGO | F17: SERVILLETA DESC S/LOGO | G17: Ciudadela | H17: 84 | I17: 87 | J17: 88 | K17: 100 | L17: 81 | M17: 89 | N17: 687.7 | O17: 0 | P17: 0 | Q17: 0 | R17: COMPRAR | S17: 687.7 | T17: -171 | U17: GASTON VECCHIO | V17: =_xlfn.XMATCH(Tabla4[[#This Row],[EAN CORREGIDO]],'Calcular necesidad'!L:L) -> 3 | W17: =TRIM(Tabla4[[#This Row],[CodInternoArti]]) -> 14047000A
A18: 2006485 | B18: 16204001A | C18: ROLLO BOLSA ARRANQUE 20 x 25 | D18: BOLSAS | E18: BOLSAS ARRANQUE | F18: BOLSAS ARRANQUE | G18: Ciudadela | H18: 11 | I18: 32 | J18: 28 | K18: 51 | L18: 11 | M18: 32 | N18: 214.5 | O18: 0 | P18: 0 | Q18: 0 | R18: COMPRAR | S18: 214.5 | T18: -43 | U18: GASTON VECCHIO | V18: =_xlfn.XMATCH(Tabla4[[#This Row],[EAN CORREGIDO]],'Calcular necesidad'!L:L) -> 15 | W18: =TRIM(Tabla4[[#This Row],[CodInternoArti]]) -> 16204001A
A19: 2006237 | B19: EMB000036 | C19: ROLLO_BOLSA_ARRANQUE_40_x_60 | D19: BOLSAS | E19: BOLSAS ARRANQUE | F19: BOLSAS ARRANQUE | G19: Ciudadela | H19: 24 | I19: 35 | J19: 35 | K19: 45 | L19: 22 | M19: 35 | N19: 254.8 | O19: 0 | P19: 0 | Q19: 0 | R19: COMPRAR | S19: 254.8 | T19: -59 | U19: GASTON VECCHIO | V19: =_xlfn.XMATCH(Tabla4[[#This Row],[EAN CORREGIDO]],'Calcular necesidad'!L:L) -> 24 | W19: =TRIM(Tabla4[[#This Row],[CodInternoArti]]) -> EMB000036
A20: 2006663 | B20: LIM000155 | C20: ROLLO ALUMINIO 45cm x 10mts | D20: PAPEL | E20: ROLLO INDUSTRIAL | F20: PAPEL ALUMINIO | G20: Ciudadela | H20: 2 | J20: 2 | L20: 2 | N20: 7.8 | O20: 0 | P20: 0 | Q20: 0 | R20: COMPRAR | S20: 7.8 | T20: -2 | U20: GASTON VECCHIO | V20: =_xlfn.XMATCH(Tabla4[[#This Row],[EAN CORREGIDO]],'Calcular necesidad'!L:L) -> 31 | W20: =TRIM(Tabla4[[#This Row],[CodInternoArti]]) -> LIM000155
A21: 2006209 | B21: 14044013A | C21: ROLLO PAPEL MANTECA | D21: PAPEL | E21: DESCARTABLES | F21: PAPEL MANTECA | G21: Ciudadela | I21: 4 | M21: 4 | N21: 10.4 | O21: 0 | P21: 0 | Q21: 0 | R21: COMPRAR | S21: 10.4 | T21: -4 | U21: GASTON VECCHIO | V21: =_xlfn.XMATCH(Tabla4[[#This Row],[EAN CORREGIDO]],'Calcular necesidad'!L:L) -> 22 | W21: =TRIM(Tabla4[[#This Row],[CodInternoArti]]) -> 14044013A
A22: 2006170 | B22: 14047009A | C22: SERVILLETA BCA 24X24 X1000U S/LOGO | D22: DESCARTABLES | E22: SERVILLETAS DESC S/LOGO | F22: SERVILLETA DESC S/LOGO | G22: Ciudadela | H22: 1 | K22: 3 | L22: 1 | N22: 6.5 | O22: 0 | P22: 0 | Q22: 0 | R22: COMPRAR | S22: 6.5 | T22: -1 | U22: GASTON VECCHIO | V22: =_xlfn.XMATCH(Tabla4[[#This Row],[EAN CORREGIDO]],'Calcular necesidad'!L:L) -> 18 | W22: =TRIM(Tabla4[[#This Row],[CodInternoArti]]) -> 14047009A
A23: 2006422 | B23: BAZ000387 | C23: DELANTALES DESCARTABLES X 100 | D23: DESCARTABLES | E23: DELANTALES DESCARTABLES | F23: DELANTAL DESCARTABLE | G23: Ciudadela | H23: 10 | I23: 10 | J23: 10 | K23: 11 | L23: 10 | M23: 10 | N23: 79.3 | O23: 0 | P23: 0 | Q23: 0 | R23: COMPRAR | S23: 79.3 | T23: -20 | U23: GASTON VECCHIO | V23: =_xlfn.XMATCH(Tabla4[[#This Row],[EAN CORREGIDO]],'Calcular necesidad'!L:L) -> 20 | W23: =TRIM(Tabla4[[#This Row],[CodInternoArti]]) -> BAZ000387
A24: 2006238 | B24: EMB000037 | C24: ROLLO_BOLSA_ARRANQUE_45_x_60 | D24: BOLSAS | E24: BOLSAS ARRANQUE | F24: BOLSAS ARRANQUE | G24: Ciudadela | H24: 3 | I24: 21 | J24: 3 | K24: 3 | L24: 3 | M24: 21 | N24: 70.2 | O24: 0 | P24: 0 | Q24: 0 | R24: COMPRAR | S24: 70.2 | T24: -24 | U24: GASTON VECCHIO | V24: =_xlfn.XMATCH(Tabla4[[#This Row],[EAN CORREGIDO]],'Calcular necesidad'!L:L) -> 27 | W24: =TRIM(Tabla4[[#This Row],[CodInternoArti]]) -> EMB000037
A25: 2007032 | B25: 17030002A | C25: GUANTES DE POLIPROPILENO x100U | D25: VARIOS | E25: GUANTES DE POLIPROPILENO | F25: GUANTE POLIPROPILENO | G25: Ciudadela | H25: 6 | I25: 3 | J25: 7 | K25: 4 | L25: 6 | M25: 3 | N25: 37.7 | O25: 0 | P25: 0 | Q25: 0 | R25: COMPRAR | S25: 37.7 | T25: -9 | U25: GASTON VECCHIO | V25: =_xlfn.XMATCH(Tabla4[[#This Row],[EAN CORREGIDO]],'Calcular necesidad'!L:L) -> 30 | W25: =TRIM(Tabla4[[#This Row],[CodInternoArti]]) -> 17030002A
A26: 2006740 | B26: 7796613305498 | C26: PLATOS DESCARTABLES X 50 UNID | D26: PLATOS | E26: PLATOS | F26: PLATOS DESCARTABLES | G26: Ciudadela | H26: 2 | I26: 2 | J26: 2 | K26: 2 | L26: 2 | M26: 2 | N26: 15.6 | O26: 0 | P26: 0 | Q26: 0 | R26: COMPRAR | S26: 15.6 | T26: -4 | U26: GASTON VECCHIO | V26: =_xlfn.XMATCH(Tabla4[[#This Row],[EAN CORREGIDO]],'Calcular necesidad'!L:L) -> 37 | W26: =TRIM(Tabla4[[#This Row],[CodInternoArti]]) -> 7796613305498
A27: 2006396 | B27: 17146007A | C27: PAPEL ALUMINIO x 1 KG | D27: PAPEL | E27: DESCARTABLES | F27: PAPEL ALUMINIO | G27: Ciudadela | H27: 12 | I27: 7 | J27: 8 | K27: 8 | L27: 11 | M27: 7 | N27: 68.9 | O27: 0 | P27: 0 | Q27: 0 | R27: COMPRAR | S27: 68.9 | T27: -19 | U27: GASTON VECCHIO | V27: =_xlfn.XMATCH(Tabla4[[#This Row],[EAN CORREGIDO]],'Calcular necesidad'!L:L) -> 26 | W27: =TRIM(Tabla4[[#This Row],[CodInternoArti]]) -> 17146007A
A28: NO SE ENCUENTRA EAN | B28: BAZ000524 | C28: DEGUSTADOR X 1000 U | D28: COCINA | E28: BAZAR | F28: DEGUSTADORES | G28: Ciudadela | J28: 2 | L28: 2 | N28: 5.2 | O28: 0 | P28: 0 | Q28: 0 | R28: COMPRAR | S28: 5.2 | T28: 0 | U28: GASTON VECCHIO | V28: =_xlfn.XMATCH(Tabla4[[#This Row],[EAN CORREGIDO]],'Calcular necesidad'!L:L) -> 195 | W28: =TRIM(Tabla4[[#This Row],[CodInternoArti]]) -> BAZ000524
A29: 2006272 | B29: EMB000035 | C29: ROLLO_BOLSA_ARRANQUE_35_x_45 | D29: BOLSAS | E29: BOLSAS ARRANQUE | F29: BOLSAS ARRANQUE | G29: Ciudadela | H29: 19 | I29: 18 | J29: 20 | K29: 19 | L29: 18 | M29: 18 | N29: 145.6 | O29: 0 | P29: 0 | Q29: 0 | R29: COMPRAR | S29: 145.6 | T29: -37 | U29: GASTON VECCHIO | V29: =_xlfn.XMATCH(Tabla4[[#This Row],[EAN CORREGIDO]],'Calcular necesidad'!L:L) -> 21 | W29: =TRIM(Tabla4[[#This Row],[CodInternoArti]]) -> EMB000035
A30: 2006143 | B30: EMB000034 | C30: ROLLO BOLSA ARRANQUE 20 x 25 | D30: BOLSAS | E30: BOLSAS ARRANQUE | F30: BOLSAS ARRANQUE | G30: Ciudadela | H30: 1 | I30: 1 | J30: 1 | K30: 2 | M30: 1 | N30: 7.8 | O30: 0 | P30: 0 | Q30: 0 | R30: COMPRAR | S30: 7.8 | T30: -2 | U30: GASTON VECCHIO | V30: =_xlfn.XMATCH(Tabla4[[#This Row],[EAN CORREGIDO]],'Calcular necesidad'!L:L) -> 34 | W30: =TRIM(Tabla4[[#This Row],[CodInternoArti]]) -> EMB000034
A31: 2006176 | B31: 7790321020206 | C31: CUCHILLO PLAST DESCARTABLE x 1000 U | D31: CUBIERTOS DESC | E31: CUCHILLOS | F31: CUCHILLOS | G31: Ciudadela | H31: 20 | I31: 37 | J31: 20 | K31: 38 | L31: 17 | M31: 36 | N31: 218.4 | O31: 0 | P31: 0 | Q31: 0 | R31: COMPRAR | S31: 218.4 | T31: -57 | U31: GASTON VECCHIO | V31: =_xlfn.XMATCH(Tabla4[[#This Row],[EAN CORREGIDO]],'Calcular necesidad'!L:L) -> 44 | W31: =TRIM(Tabla4[[#This Row],[CodInternoArti]]) -> 7790321020206
A32: 2006651 | B32: 7790321020256 | C32: TAPA 101 x 100 U | D32: TAPAS BAND DESC | E32: TAPAS PLASTICAS | F32: TAPA 101 | G32: Ciudadela | H32: 198 | I32: 205 | J32: 195 | K32: 218 | L32: 169 | M32: 192 | N32: 1530.1 | O32: 0 | P32: 0 | Q32: 0 | R32: COMPRAR | S32: 1530.1 | T32: -403 | U32: GASTON VECCHIO | V32: =_xlfn.XMATCH(Tabla4[[#This Row],[EAN CORREGIDO]],'Calcular necesidad'!L:L) -> 45 | W32: =TRIM(Tabla4[[#This Row],[CodInternoArti]]) -> 7790321020256
A33: 2006679 | B33: 7790321007512 | C33: BAND ALUM R3/F2275 X600U | D33: BANDEJAS DESC | E33: BANDEJAS ALUMINIO | F33: BAND ALUMINIO R3 | G33: Ciudadela | H33: 30 | I33: 30 | J33: 30 | K33: 30 | L33: 30 | M33: 30 | N33: 234 | O33: 0 | P33: 0 | Q33: 0 | R33: COMPRAR | S33: 234 | T33: -60 | U33: GASTON VECCHIO | V33: =_xlfn.XMATCH(Tabla4[[#This Row],[EAN CORREGIDO]],'Calcular necesidad'!L:L) -> 48 | W33: =TRIM(Tabla4[[#This Row],[CodInternoArti]]) -> 7790321007512
A34: 2006379 | B34: LIM000292 | C34: GUANTE NITRILO X100U | D34: GUANTES | E34: GUANTES NITRILO | F34: GUANTE NITRILO | G34: Ciudadela | H34: 21 | I34: 19 | J34: 11 | K34: 25 | M34: 12 | N34: 114.4 | O34: 0 | P34: 0 | Q34: 0 | R34: COMPRAR | S34: 114.4 | T34: -40 | U34: GASTON VECCHIO | V34: =_xlfn.XMATCH(Tabla4[[#This Row],[EAN CORREGIDO]],'Calcular necesidad'!L:L) -> 35 | W34: =TRIM(Tabla4[[#This Row],[CodInternoArti]]) -> LIM000292
A35: 2006427 | B35: 7790321020106 | C35: BANDEJAS PLASTICAS 101 x 100 U RECTANGULAR | D35: BANDEJAS DESC | E35: BANDEJAS PLASTICAS | F35: BAND 101 | G35: Ciudadela | H35: 51 | I35: 69 | J35: 72 | K35: 59 | L35: 77 | M35: 79 | N35: 529.1 | O35: 0 | P35: 0 | Q35: 0 | R35: COMPRAR | S35: 529.1 | T35: -120 | U35: GASTON VECCHIO | V35: =_xlfn.XMATCH(Tabla4[[#This Row],[EAN CORREGIDO]],'Calcular necesidad'!L:L) -> 40 | W35: =TRIM(Tabla4[[#This Row],[CodInternoArti]]) -> 7790321020106
A36: 2006410 | B36: 7790321020156 | C36: VO BOLSA CAMIS NEG 45X60X100UN | D36: BOLSAS | E36: BOLSAS CAMISETA | F36: BOLSAS CAMISETA | G36: Ciudadela | H36: 2 | I36: 2 | N36: 5.2 | O36: 0 | P36: 0 | Q36: 0 | R36: COMPRAR | S36: 5.2 | T36: -4 | U36: GASTON VECCHIO | V36: =_xlfn.XMATCH(Tabla4[[#This Row],[EAN CORREGIDO]],'Calcular necesidad'!L:L) -> 50 | W36: =TRIM(Tabla4[[#This Row],[CodInternoArti]]) -> 7790321020156
A37: 2006383 | B37: LIM000324 | C37: BARBIJOS X 100 U | D37: VARIOS | E37: DESCARTABLES | F37: BARBIJO DESCARTABLE | G37: Ciudadela | H37: 3 | I37: 14 | J37: 1 | K37: 4 | L37: 1 | M37: 4 | N37: 35.1 | O37: 0 | P37: 0 | Q37: 0 | R37: COMPRAR | S37: 35.1 | T37: -17 | U37: GASTON VECCHIO | V37: =_xlfn.XMATCH(Tabla4[[#This Row],[EAN CORREGIDO]],'Calcular necesidad'!L:L) -> 29 | W37: =TRIM(Tabla4[[#This Row],[CodInternoArti]]) -> LIM000324
A38: 2006424 | B38: 7790321006512 | C38: BAND. ALUMINIO R5/F2100x600 U | D38: BANDEJAS DESC | E38: BANDEJAS ALUMINIO | F38: BAND ALUMINIO R5 | G38: Ciudadela | H38: 2 | I38: 2 | J38: 2 | K38: 2 | L38: 2 | M38: 4 | N38: 18.2 | O38: 0 | P38: 0 | Q38: 0 | R38: COMPRAR | S38: 18.2 | T38: -4 | U38: GASTON VECCHIO | V38: =_xlfn.XMATCH(Tabla4[[#This Row],[EAN CORREGIDO]],'Calcular necesidad'!L:L) -> 52 | W38: =TRIM(Tabla4[[#This Row],[CodInternoArti]]) -> 7790321006512
A39: 2006489 | B39: EMB000038 | C39: ROLLO_BOLSA_ARRANQUE_60_x_90_ | D39: BOLSAS | E39: BOLSAS ARRANQUE | F39: BOLSAS ARRANQUE | G39: Ciudadela | H39: 9 | I39: 21 | J39: 29 | K39: 38 | L39: 9 | M39: 21 | N39: 165.1 | O39: 0 | P39: 0 | Q39: 0 | R39: COMPRAR | S39: 165.1 | T39: -30 | U39: GASTON VECCHIO | V39: =_xlfn.XMATCH(Tabla4[[#This Row],[EAN CORREGIDO]],'Calcular necesidad'!L:L) -> 28 | W39: =TRIM(Tabla4[[#This Row],[CodInternoArti]]) -> EMB000038
A40: 2006739 | B40: 7790321020237 | C40: MANTEL IND 40X30X1000U GL | D40: VARIOS | E40: DESCARTABLES | F40: MANTEL LOGO GL | G40: Ciudadela | J40: 1 | N40: 1.3 | O40: 0 | P40: 0 | Q40: 0 | R40: COMPRAR | S40: 1.3 | T40: 0 | U40: GASTON VECCHIO | V40: =_xlfn.XMATCH(Tabla4[[#This Row],[EAN CORREGIDO]],'Calcular necesidad'!L:L) -> 75 | W40: =TRIM(Tabla4[[#This Row],[CodInternoArti]]) -> 7790321020237
...

Sheet Calcular necesidad
A1: Esta en "Tablar articulos"? | B1: "Necesidad x Familia"? | C1: CodInternoArti | D1: DescripcionArti | E1: Familia | F1: UM | G1: Moreno | H1: Ciudadela | I1: CD Moreno 2 | J1: Operador interior | K1: CD Moreno 3 | L1: Ean Corregido
A2: =IF(ISNUMBER(_xlfn.XMATCH(Tabla3[[#This Row],[CodInternoArti]],'Tabla Articulos'!B:B)),"OK","NO ESTA") -> OK | B2: =IF(ISNUMBER(_xlfn.XMATCH('Calcular necesidad'!E:E,'Necesidad por familia'!A:A)),"OK","NO ESTA") -> OK | C2: 13044000A | D2: RESINITE (FILM DE PVC) x ROLLO | E2: =_xlfn.XLOOKUP(C2,'Tabla Articulos'!B:B,'Tabla Articulos'!D:D) -> FILM PVC 38 | F2: =_xlfn.XLOOKUP(C2,'Tabla Articulos'!B:B,'Tabla Articulos'!E:E) -> 1 | G2: =SUM( SUMIFS(MRP!$H$2:$H$221, MRP!$B$2:$B$221, $C2, MRP!$G$2:$G$221, G$1), SUMIFS(MRP!$I$2:$I$221, MRP!$B$2:$B$221, $C2, MRP!$G$2:$G$221, G$1), SUMIFS(MRP!$J$2:$J$221, MRP!$B$2:$B$221, $C2, MRP!$G$2:$G$221, G$1), SUMIFS(MRP!$K$2:$K$221, MRP!$B$2:$B$221, $C2, MRP!$G$2:$G$221, G$1), SUMIFS(MRP!$L$2:$L$221, MRP!$B$2:$B$221, $C2, MRP!$G$2:$G$221, G$1) )*F2 -> 0 | H2: =SUM( SUMIFS(MRP!$H$2:$H$221, MRP!$B$2:$B$221, $C2, MRP!$G$2:$G$221, H$1), SUMIFS(MRP!$I$2:$I$221, MRP!$B$2:$B$221, $C2, MRP!$G$2:$G$221, H$1), SUMIFS(MRP!$J$2:$J$221, MRP!$B$2:$B$221, $C2, MRP!$G$2:$G$221, H$1), SUMIFS(MRP!$K$2:$K$221, MRP!$B$2:$B$221, $C2, MRP!$G$2:$G$221, H$1), SUMIFS(MRP!$L$2:$L$221, MRP!$B$2:$B$221, $C2, MRP!$G$2:$G$221, H$1) )*F2 -> 229 | I2: =SUM( SUMIFS(MRP!$H$2:$H$221, MRP!$B$2:$B$221, $C2, MRP!$G$2:$G$221, I$1), SUMIFS(MRP!$I$2:$I$221, MRP!$B$2:$B$221, $C2, MRP!$G$2:$G$221, I$1), SUMIFS(MRP!$J$2:$J$221, MRP!$B$2:$B$221, $C2, MRP!$G$2:$G$221, I$1), SUMIFS(MRP!$K$2:$K$221, MRP!$B$2:$B$221, $C2, MRP!$G$2:$G$221, I$1), SUMIFS(MRP!$L$2:$L$221, MRP!$B$2:$B$221, $C2, MRP!$G$2:$G$221, I$1) )*F2 -> 0 | J2: =SUM( SUMIFS(MRP!$H$2:$H$221, MRP!$B$2:$B$221, $C2, MRP!$G$2:$G$221, J$1), SUMIFS(MRP!$I$2:$I$221, MRP!$B$2:$B$221, $C2, MRP!$G$2:$G$221, J$1), SUMIFS(MRP!$J$2:$J$221, MRP!$B$2:$B$221, $C2, MRP!$G$2:$G$221, J$1), SUMIFS(MRP!$K$2:$K$221, MRP!$B$2:$B$221, $C2, MRP!$G$2:$G$221, J$1), SUMIFS(MRP!$L$2:$L$221, MRP!$B$2:$B$221, $C2, MRP!$G$2:$G$221, J$1) )*F2 -> 0 | K2: =SUM( SUMIFS(MRP!$H$2:$H$221, MRP!$B$2:$B$221, $C2, MRP!$G$2:$G$221, K$1), SUMIFS(MRP!$I$2:$I$221, MRP!$B$2:$B$221, $C2, MRP!$G$2:$G$221, K$1), SUMIFS(MRP!$J$2:$J$221, MRP!$B$2:$B$221, $C2, MRP!$G$2:$G$221, K$1), SUMIFS(MRP!$K$2:$K$221, MRP!$B$2:$B$221, $C2, MRP!$G$2:$G$221, K$1), SUMIFS(MRP!$L$2:$L$221, MRP!$B$2:$B$221, $C2, MRP!$G$2:$G$221, K$1) )*F2 -> 0 | L2: =TRIM(Tabla3[[#This Row],[CodInternoArti]]) -> 13044000A
A3: =IF(ISNUMBER(_xlfn.XMATCH(Tabla3[[#This Row],[CodInternoArti]],'Tabla Articulos'!B:B)),"OK","NO ESTA") -> OK | B3: =IF(ISNUMBER(_xlfn.XMATCH('Calcular necesidad'!E:E,'Necesidad por familia'!A:A)),"OK","NO ESTA") -> OK | C3: 14047000A | D3: SERVILLE BCA 33X32X1000U S/LOGO | E3: =_xlfn.XLOOKUP(C3,'Tabla Articulos'!B:B,'Tabla Articulos'!D:D) -> SERVILLETA 30X30 S/LOGO | F3: =_xlfn.XLOOKUP(C3,'Tabla Articulos'!B:B,'Tabla Articulos'!E:E) -> 1000 | G3: =SUM( SUMIFS(MRP!$H$2:$H$221, MRP!$B$2:$B$221, $C3, MRP!$G$2:$G$221, G$1), SUMIFS(MRP!$I$2:$I$221, MRP!$B$2:$B$221, $C3, MRP!$G$2:$G$221, G$1), SUMIFS(MRP!$J$2:$J$221, MRP!$B$2:$B$221, $C3, MRP!$G$2:$G$221, G$1), SUMIFS(MRP!$K$2:$K$221, MRP!$B$2:$B$221, $C3, MRP!$G$2:$G$221, G$1), SUMIFS(MRP!$L$2:$L$221, MRP!$B$2:$B$221, $C3, MRP!$G$2:$G$221, G$1) )*F3 -> 0 | H3: =SUM( SUMIFS(MRP!$H$2:$H$221, MRP!$B$2:$B$221, $C3, MRP!$G$2:$G$221, H$1), SUMIFS(MRP!$I$2:$I$221, MRP!$B$2:$B$221, $C3, MRP!$G$2:$G$221, H$1), SUMIFS(MRP!$J$2:$J$221, MRP!$B$2:$B$221, $C3, MRP!$G$2:$G$221, H$1), SUMIFS(MRP!$K$2:$K$221, MRP!$B$2:$B$221, $C3, MRP!$G$2:$G$221, H$1), SUMIFS(MRP!$L$2:$L$221, MRP!$B$2:$B$221, $C3, MRP!$G$2:$G$221, H$1) )*F3 -> 440000 | I3: =SUM( SUMIFS(MRP!$H$2:$H$221, MRP!$B$2:$B$221, $C3, MRP!$G$2:$G$221, I$1), SUMIFS(MRP!$I$2:$I$221, MRP!$B$2:$B$221, $C3, MRP!$G$2:$G$221, I$1), SUMIFS(MRP!$J$2:$J$221, MRP!$B$2:$B$221, $C3, MRP!$G$2:$G$221, I$1), SUMIFS(MRP!$K$2:$K$221, MRP!$B$2:$B$221, $C3, MRP!$G$2:$G$221, I$1), SUMIFS(MRP!$L$2:$L$221, MRP!$B$2:$B$221, $C3, MRP!$G$2:$G$221, I$1) )*F3 -> 0 | J3: =SUM( SUMIFS(MRP!$H$2:$H$221, MRP!$B$2:$B$221, $C3, MRP!$G$2:$G$221, J$1), SUMIFS(MRP!$I$2:$I$221, MRP!$B$2:$B$221, $C3, MRP!$G$2:$G$221, J$1), SUMIFS(MRP!$J$2:$J$221, MRP!$B$2:$B$221, $C3, MRP!$G$2:$G$221, J$1), SUMIFS(MRP!$K$2:$K$221, MRP!$B$2:$B$221, $C3, MRP!$G$2:$G$221, J$1), SUMIFS(MRP!$L$2:$L$221, MRP!$B$2:$B$221, $C3, MRP!$G$2:$G$221, J$1) )*F3 -> 0 | K3: =SUM( SUMIFS(MRP!$H$2:$H$221, MRP!$B$2:$B$221, $C3, MRP!$G$2:$G$221, K$1), SUMIFS(MRP!$I$2:$I$221, MRP!$B$2:$B$221, $C3, MRP!$G$2:$G$221, K$1), SUMIFS(MRP!$J$2:$J$221, MRP!$B$2:$B$221, $C3, MRP!$G$2:$G$221, K$1), SUMIFS(MRP!$K$2:$K$221, MRP!$B$2:$B$221, $C3, MRP!$G$2:$G$221, K$1), SUMIFS(MRP!$L$2:$L$221, MRP!$B$2:$B$221, $C3, MRP!$G$2:$G$221, K$1) )*F3 -> 0 | L3: =TRIM(Tabla3[[#This Row],[CodInternoArti]]) -> 14047000A
A4: =IF(ISNUMBER(_xlfn.XMATCH(Tabla3[[#This Row],[CodInternoArti]],'Tabla Articulos'!B:B)),"OK","NO ESTA") -> OK | B4: =IF(ISNUMBER(_xlfn.XMATCH('Calcular necesidad'!E:E,'Necesidad por familia'!A:A)),"OK","NO ESTA") -> OK | C4: 13069000A | D4: AGITADOR x 1000 U | E4: =_xlfn.XLOOKUP(C4,'Tabla Articulos'!B:B,'Tabla Articulos'!D:D) -> AGITADOR | F4: =_xlfn.XLOOKUP(C4,'Tabla Articulos'!B:B,'Tabla Articulos'!E:E) -> 1000 | G4: =SUM( SUMIFS(MRP!$H$2:$H$221, MRP!$B$2:$B$221, $C4, MRP!$G$2:$G$221, G$1), SUMIFS(MRP!$I$2:$I$221, MRP!$B$2:$B$221, $C4, MRP!$G$2:$G$221, G$1), SUMIFS(MRP!$J$2:$J$221, MRP!$B$2:$B$221, $C4, MRP!$G$2:$G$221, G$1), SUMIFS(MRP!$K$2:$K$221, MRP!$B$2:$B$221, $C4, MRP!$G$2:$G$221, G$1), SUMIFS(MRP!$L$2:$L$221, MRP!$B$2:$B$221, $C4, MRP!$G$2:$G$221, G$1) )*F4 -> 0 | H4: =SUM( SUMIFS(MRP!$H$2:$H$221, MRP!$B$2:$B$221, $C4, MRP!$G$2:$G$221, H$1), SUMIFS(MRP!$I$2:$I$221, MRP!$B$2:$B$221, $C4, MRP!$G$2:$G$221, H$1), SUMIFS(MRP!$J$2:$J$221, MRP!$B$2:$B$221, $C4, MRP!$G$2:$G$221, H$1), SUMIFS(MRP!$K$2:$K$221, MRP!$B$2:$B$221, $C4, MRP!$G$2:$G$221, H$1), SUMIFS(MRP!$L$2:$L$221, MRP!$B$2:$B$221, $C4, MRP!$G$2:$G$221, H$1) )*F4 -> 53000 | I4: =SUM( SUMIFS(MRP!$H$2:$H$221, MRP!$B$2:$B$221, $C4, MRP!$G$2:$G$221, I$1), SUMIFS(MRP!$I$2:$I$221, MRP!$B$2:$B$221, $C4, MRP!$G$2:$G$221, I$1), SUMIFS(MRP!$J$2:$J$221, MRP!$B$2:$B$221, $C4, MRP!$G$2:$G$221, I$1), SUMIFS(MRP!$K$2:$K$221, MRP!$B$2:$B$221, $C4, MRP!$G$2:$G$221, I$1), SUMIFS(MRP!$L$2:$L$221, MRP!$B$2:$B$221, $C4, MRP!$G$2:$G$221, I$1) )*F4 -> 0 | J4: =SUM( SUMIFS(MRP!$H$2:$H$221, MRP!$B$2:$B$221, $C4, MRP!$G$2:$G$221, J$1), SUMIFS(MRP!$I$2:$I$221, MRP!$B$2:$B$221, $C4, MRP!$G$2:$G$221, J$1), SUMIFS(MRP!$J$2:$J$221, MRP!$B$2:$B$221, $C4, MRP!$G$2:$G$221, J$1), SUMIFS(MRP!$K$2:$K$221, MRP!$B$2:$B$221, $C4, MRP!$G$2:$G$221, J$1), SUMIFS(MRP!$L$2:$L$221, MRP!$B$2:$B$221, $C4, MRP!$G$2:$G$221, J$1) )*F4 -> 0 | K4: =SUM( SUMIFS(MRP!$H$2:$H$221, MRP!$B$2:$B$221, $C4, MRP!$G$2:$G$221, K$1), SUMIFS(MRP!$I$2:$I$221, MRP!$B$2:$B$221, $C4, MRP!$G$2:$G$221, K$1), SUMIFS(MRP!$J$2:$J$221, MRP!$B$2:$B$221, $C4, MRP!$G$2:$G$221, K$1), SUMIFS(MRP!$K$2:$K$221, MRP!$B$2:$B$221, $C4, MRP!$G$2:$G$221, K$1), SUMIFS(MRP!$L$2:$L$221, MRP!$B$2:$B$221, $C4, MRP!$G$2:$G$221, K$1) )*F4 -> 0 | L4: =TRIM(Tabla3[[#This Row],[CodInternoArti]]) -> 13069000A
A5: =IF(ISNUMBER(_xlfn.XMATCH(Tabla3[[#This Row],[CodInternoArti]],'Tabla Articulos'!B:B)),"OK","NO ESTA") -> OK | B5: =IF(ISNUMBER(_xlfn.XMATCH('Calcular necesidad'!E:E,'Necesidad por familia'!A:A)),"OK","NO ESTA") -> OK | C5: 16204006A | D5: ROLLO BOLSA ARRANQUE 60 x 90 | E5: =_xlfn.XLOOKUP(C5,'Tabla Articulos'!B:B,'Tabla Articulos'!D:D) -> ARRANQUE 60X90 | F5: =_xlfn.XLOOKUP(C5,'Tabla Articulos'!B:B,'Tabla Articulos'!E:E) -> 1 | G5: =SUM( SUMIFS(MRP!$H$2:$H$221, MRP!$B$2:$B$221, $C5, MRP!$G$2:$G$221, G$1), SUMIFS(MRP!$I$2:$I$221, MRP!$B$2:$B$221, $C5, MRP!$G$2:$G$221, G$1), SUMIFS(MRP!$J$2:$J$221, MRP!$B$2:$B$221, $C5, MRP!$G$2:$G$221, G$1), SUMIFS(MRP!$K$2:$K$221, MRP!$B$2:$B$221, $C5, MRP!$G$2:$G$221, G$1), SUMIFS(MRP!$L$2:$L$221, MRP!$B$2:$B$221, $C5, MRP!$G$2:$G$221, G$1) )*F5 -> 0 | H5: =SUM( SUMIFS(MRP!$H$2:$H$221, MRP!$B$2:$B$221, $C5, MRP!$G$2:$G$221, H$1), SUMIFS(MRP!$I$2:$I$221, MRP!$B$2:$B$221, $C5, MRP!$G$2:$G$221, H$1), SUMIFS(MRP!$J$2:$J$221, MRP!$B$2:$B$221, $C5, MRP!$G$2:$G$221, H$1), SUMIFS(MRP!$K$2:$K$221, MRP!$B$2:$B$221, $C5, MRP!$G$2:$G$221, H$1), SUMIFS(MRP!$L$2:$L$221, MRP!$B$2:$B$221, $C5, MRP!$G$2:$G$221, H$1) )*F5 -> 77 | I5: =SUM( SUMIFS(MRP!$H$2:$H$221, MRP!$B$2:$B$221, $C5, MRP!$G$2:$G$221, I$1), SUMIFS(MRP!$I$2:$I$221, MRP!$B$2:$B$221, $C5, MRP!$G$2:$G$221, I$1), SUMIFS(MRP!$J$2:$J$221, MRP!$B$2:$B$221, $C5, MRP!$G$2:$G$221, I$1), SUMIFS(MRP!$K$2:$K$221, MRP!$B$2:$B$221, $C5, MRP!$G$2:$G$221, I$1), SUMIFS(MRP!$L$2:$L$221, MRP!$B$2:$B$221, $C5, MRP!$G$2:$G$221, I$1) )*F5 -> 0 | J5: =SUM( SUMIFS(MRP!$H$2:$H$221, MRP!$B$2:$B$221, $C5, MRP!$G$2:$G$221, J$1), SUMIFS(MRP!$I$2:$I$221, MRP!$B$2:$B$221, $C5, MRP!$G$2:$G$221, J$1), SUMIFS(MRP!$J$2:$J$221, MRP!$B$2:$B$221, $C5, MRP!$G$2:$G$221, J$1), SUMIFS(MRP!$K$2:$K$221, MRP!$B$2:$B$221, $C5, MRP!$G$2:$G$221, J$1), SUMIFS(MRP!$L$2:$L$221, MRP!$B$2:$B$221, $C5, MRP!$G$2:$G$221, J$1) )*F5 -> 0 | K5: =SUM( SUMIFS(MRP!$H$2:$H$221, MRP!$B$2:$B$221, $C5, MRP!$G$2:$G$221, K$1), SUMIFS(MRP!$I$2:$I$221, MRP!$B$2:$B$221, $C5, MRP!$G$2:$G$221, K$1), SUMIFS(MRP!$J$2:$J$221, MRP!$B$2:$B$221, $C5, MRP!$G$2:$G$221, K$1), SUMIFS(MRP!$K$2:$K$221, MRP!$B$2:$B$221, $C5, MRP!$G$2:$G$221, K$1), SUMIFS(MRP!$L$2:$L$221, MRP!$B$2:$B$221, $C5, MRP!$G$2:$G$221, K$1) )*F5 -> 0 | L5: =TRIM(Tabla3[[#This Row],[CodInternoArti]]) -> 16204006A
A6: =IF(ISNUMBER(_xlfn.XMATCH(Tabla3[[#This Row],[CodInternoArti]],'Tabla Articulos'!B:B)),"OK","NO ESTA") -> OK | B6: =IF(ISNUMBER(_xlfn.XMATCH('Calcular necesidad'!E:E,'Necesidad por familia'!A:A)),"OK","NO ESTA") -> OK | C6: 16204004A | D6: ROLLO BOLSA ARRANQUE 45 x 60 | E6: =_xlfn.XLOOKUP(C6,'Tabla Articulos'!B:B,'Tabla Articulos'!D:D) -> ARRANQUE 40X60 | F6: =_xlfn.XLOOKUP(C6,'Tabla Articulos'!B:B,'Tabla Articulos'!E:E) -> 1 | G6: =SUM( SUMIFS(MRP!$H$2:$H$221, MRP!$B$2:$B$221, $C6, MRP!$G$2:$G$221, G$1), SUMIFS(MRP!$I$2:$I$221, MRP!$B$2:$B$221, $C6, MRP!$G$2:$G$221, G$1), SUMIFS(MRP!$J$2:$J$221, MRP!$B$2:$B$221, $C6, MRP!$G$2:$G$221, G$1), SUMIFS(MRP!$K$2:$K$221, MRP!$B$2:$B$221, $C6, MRP!$G$2:$G$221, G$1), SUMIFS(MRP!$L$2:$L$221, MRP!$B$2:$B$221, $C6, MRP!$G$2:$G$221, G$1) )*F6 -> 0 | H6: =SUM( SUMIFS(MRP!$H$2:$H$221, MRP!$B$2:$B$221, $C6, MRP!$G$2:$G$221, H$1), SUMIFS(MRP!$I$2:$I$221, MRP!$B$2:$B$221, $C6, MRP!$G$2:$G$221, H$1), SUMIFS(MRP!$J$2:$J$221, MRP!$B$2:$B$221, $C6, MRP!$G$2:$G$221, H$1), SUMIFS(MRP!$K$2:$K$221, MRP!$B$2:$B$221, $C6, MRP!$G$2:$G$221, H$1), SUMIFS(MRP!$L$2:$L$221, MRP!$B$2:$B$221, $C6, MRP!$G$2:$G$221, H$1) )*F6 -> 30 | I6: =SUM( SUMIFS(MRP!$H$2:$H$221, MRP!$B$2:$B$221, $C6, MRP!$G$2:$G$221, I$1), SUMIFS(MRP!$I$2:$I$221, MRP!$B$2:$B$221, $C6, MRP!$G$2:$G$221, I$1), SUMIFS(MRP!$J$2:$J$221, MRP!$B$2:$B$221, $C6, MRP!$G$2:$G$221, I$1), SUMIFS(MRP!$K$2:$K$221, MRP!$B$2:$B$221, $C6, MRP!$G$2:$G$221, I$1), SUMIFS(MRP!$L$2:$L$221, MRP!$B$2:$B$221, $C6, MRP!$G$2:$G$221, I$1) )*F6 -> 0 | J6: =SUM( SUMIFS(MRP!$H$2:$H$221, MRP!$B$2:$B$221, $C6, MRP!$G$2:$G$221, J$1), SUMIFS(MRP!$I$2:$I$221, MRP!$B$2:$B$221, $C6, MRP!$G$2:$G$221, J$1), SUMIFS(MRP!$J$2:$J$221, MRP!$B$2:$B$221, $C6, MRP!$G$2:$G$221, J$1), SUMIFS(MRP!$K$2:$K$221, MRP!$B$2:$B$221, $C6, MRP!$G$2:$G$221, J$1), SUMIFS(MRP!$L$2:$L$221, MRP!$B$2:$B$221, $C6, MRP!$G$2:$G$221, J$1) )*F6 -> 0 | K6: =SUM( SUMIFS(MRP!$H$2:$H$221, MRP!$B$2:$B$221, $C6, MRP!$G$2:$G$221, K$1), SUMIFS(MRP!$I$2:$I$221, MRP!$B$2:$B$221, $C6, MRP!$G$2:$G$221, K$1), SUMIFS(MRP!$J$2:$J$221, MRP!$B$2:$B$221, $C6, MRP!$G$2:$G$221, K$1), SUMIFS(MRP!$K$2:$K$221, MRP!$B$2:$B$221, $C6, MRP!$G$2:$G$221, K$1), SUMIFS(MRP!$L$2:$L$221, MRP!$B$2:$B$221, $C6, MRP!$G$2:$G$221, K$1) )*F6 -> 0 | L6: =TRIM(Tabla3[[#This Row],[CodInternoArti]]) -> 16204004A
A7: =IF(ISNUMBER(_xlfn.XMATCH(Tabla3[[#This Row],[CodInternoArti]],'Tabla Articulos'!B:B)),"OK","NO ESTA") -> OK | B7: =IF(ISNUMBER(_xlfn.XMATCH('Calcular necesidad'!E:E,'Necesidad por familia'!A:A)),"OK","NO ESTA") -> OK | C7: 16208001A | D7: ROLLO DE BOLSA DE ARRANQUE 20 x 30 | E7: =_xlfn.XLOOKUP(C7,'Tabla Articulos'!B:B,'Tabla Articulos'!D:D) -> ARRANQUE 20X30 | F7: =_xlfn.XLOOKUP(C7,'Tabla Articulos'!B:B,'Tabla Articulos'!E:E) -> 1 | G7: =SUM( SUMIFS(MRP!$H$2:$H$221, MRP!$B$2:$B$221, $C7, MRP!$G$2:$G$221, G$1), SUMIFS(MRP!$I$2:$I$221, MRP!$B$2:$B$221, $C7, MRP!$G$2:$G$221, G$1), SUMIFS(MRP!$J$2:$J$221, MRP!$B$2:$B$221, $C7, MRP!$G$2:$G$221, G$1), SUMIFS(MRP!$K$2:$K$221, MRP!$B$2:$B$221, $C7, MRP!$G$2:$G$221, G$1), SUMIFS(MRP!$L$2:$L$221, MRP!$B$2:$B$221, $C7, MRP!$G$2:$G$221, G$1) )*F7 -> 0 | H7: =SUM( SUMIFS(MRP!$H$2:$H$221, MRP!$B$2:$B$221, $C7, MRP!$G$2:$G$221, H$1), SUMIFS(MRP!$I$2:$I$221, MRP!$B$2:$B$221, $C7, MRP!$G$2:$G$221, H$1), SUMIFS(MRP!$J$2:$J$221, MRP!$B$2:$B$221, $C7, MRP!$G$2:$G$221, H$1), SUMIFS(MRP!$K$2:$K$221, MRP!$B$2:$B$221, $C7, MRP!$G$2:$G$221, H$1), SUMIFS(MRP!$L$2:$L$221, MRP!$B$2:$B$221, $C7, MRP!$G$2:$G$221, H$1) )*F7 -> 102 | I7: =SUM( SUMIFS(MRP!$H$2:$H$221, MRP!$B$2:$B$221, $C7, MRP!$G$2:$G$221, I$1), SUMIFS(MRP!$I$2:$I$221, MRP!$B$2:$B$221, $C7, MRP!$G$2:$G$221, I$1), SUMIFS(MRP!$J$2:$J$221, MRP!$B$2:$B$221, $C7, MRP!$G$2:$G$221, I$1), SUMIFS(MRP!$K$2:$K$221, MRP!$B$2:$B$221, $C7, MRP!$G$2:$G$221, I$1), SUMIFS(MRP!$L$2:$L$221, MRP!$B$2:$B$221, $C7, MRP!$G$2:$G$221, I$1) )*F7 -> 0 | J7: =SUM( SUMIFS(MRP!$H$2:$H$221, MRP!$B$2:$B$221, $C7, MRP!$G$2:$G$221, J$1), SUMIFS(MRP!$I$2:$I$221, MRP!$B$2:$B$221, $C7, MRP!$G$2:$G$221, J$1), SUMIFS(MRP!$J$2:$J$221, MRP!$B$2:$B$221, $C7, MRP!$G$2:$G$221, J$1), SUMIFS(MRP!$K$2:$K$221, MRP!$B$2:$B$221, $C7, MRP!$G$2:$G$221, J$1), SUMIFS(MRP!$L$2:$L$221, MRP!$B$2:$B$221, $C7, MRP!$G$2:$G$221, J$1) )*F7 -> 0 | K7: =SUM( SUMIFS(MRP!$H$2:$H$221, MRP!$B$2:$B$221, $C7, MRP!$G$2:$G$221, K$1), SUMIFS(MRP!$I$2:$I$221, MRP!$B$2:$B$221, $C7, MRP!$G$2:$G$221, K$1), SUMIFS(MRP!$J$2:$J$221, MRP!$B$2:$B$221, $C7, MRP!$G$2:$G$221, K$1), SUMIFS(MRP!$K$2:$K$221, MRP!$B$2:$B$221, $C7, MRP!$G$2:$G$221, K$1), SUMIFS(MRP!$L$2:$L$221, MRP!$B$2:$B$221, $C7, MRP!$G$2:$G$221, K$1) )*F7 -> 0 | L7: =TRIM(Tabla3[[#This Row],[CodInternoArti]]) -> 16208001A
A8: =IF(ISNUMBER(_xlfn.XMATCH(Tabla3[[#This Row],[CodInternoArti]],'Tabla Articulos'!B:B)),"OK","NO ESTA") -> OK | B8: =IF(ISNUMBER(_xlfn.XMATCH('Calcular necesidad'!E:E,'Necesidad por familia'!A:A)),"OK","NO ESTA") -> OK | C8: 17030001A | D8: GUANTE DE LATEX x 100 UNID | E8: =_xlfn.XLOOKUP(C8,'Tabla Articulos'!B:B,'Tabla Articulos'!D:D) -> GUANTE LATEX M | F8: =_xlfn.XLOOKUP(C8,'Tabla Articulos'!B:B,'Tabla Articulos'!E:E) -> 100 | G8: =SUM( SUMIFS(MRP!$H$2:$H$221, MRP!$B$2:$B$221, $C8, MRP!$G$2:$G$221, G$1), SUMIFS(MRP!$I$2:$I$221, MRP!$B$2:$B$221, $C8, MRP!$G$2:$G$221, G$1), SUMIFS(MRP!$J$2:$J$221, MRP!$B$2:$B$221, $C8, MRP!$G$2:$G$221, G$1), SUMIFS(MRP!$K$2:$K$221, MRP!$B$2:$B$221, $C8, MRP!$G$2:$G$221, G$1), SUMIFS(MRP!$L$2:$L$221, MRP!$B$2:$B$221, $C8, MRP!$G$2:$G$221, G$1) )*F8 -> 0 | H8: =SUM( SUMIFS(MRP!$H$2:$H$221, MRP!$B$2:$B$221, $C8, MRP!$G$2:$G$221, H$1), SUMIFS(MRP!$I$2:$I$221, MRP!$B$2:$B$221, $C8, MRP!$G$2:$G$221, H$1), SUMIFS(MRP!$J$2:$J$221, MRP!$B$2:$B$221, $C8, MRP!$G$2:$G$221, H$1), SUMIFS(MRP!$K$2:$K$221, MRP!$B$2:$B$221, $C8, MRP!$G$2:$G$221, H$1), SUMIFS(MRP!$L$2:$L$221, MRP!$B$2:$B$221, $C8, MRP!$G$2:$G$221, H$1) )*F8 -> 41400 | I8: =SUM( SUMIFS(MRP!$H$2:$H$221, MRP!$B$2:$B$221, $C8, MRP!$G$2:$G$221, I$1), SUMIFS(MRP!$I$2:$I$221, MRP!$B$2:$B$221, $C8, MRP!$G$2:$G$221, I$1), SUMIFS(MRP!$J$2:$J$221, MRP!$B$2:$B$221, $C8, MRP!$G$2:$G$221, I$1), SUMIFS(MRP!$K$2:$K$221, MRP!$B$2:$B$221, $C8, MRP!$G$2:$G$221, I$1), SUMIFS(MRP!$L$2:$L$221, MRP!$B$2:$B$221, $C8, MRP!$G$2:$G$221, I$1) )*F8 -> 0 | J8: =SUM( SUMIFS(MRP!$H$2:$H$221, MRP!$B$2:$B$221, $C8, MRP!$G$2:$G$221, J$1), SUMIFS(MRP!$I$2:$I$221, MRP!$B$2:$B$221, $C8, MRP!$G$2:$G$221, J$1), SUMIFS(MRP!$J$2:$J$221, MRP!$B$2:$B$221, $C8, MRP!$G$2:$G$221, J$1), SUMIFS(MRP!$K$2:$K$221, MRP!$B$2:$B$221, $C8, MRP!$G$2:$G$221, J$1), SUMIFS(MRP!$L$2:$L$221, MRP!$B$2:$B$221, $C8, MRP!$G$2:$G$221, J$1) )*F8 -> 0 | K8: =SUM( SUMIFS(MRP!$H$2:$H$221, MRP!$B$2:$B$221, $C8, MRP!$G$2:$G$221, K$1), SUMIFS(MRP!$I$2:$I$221, MRP!$B$2:$B$221, $C8, MRP!$G$2:$G$221, K$1), SUMIFS(MRP!$J$2:$J$221, MRP!$B$2:$B$221, $C8, MRP!$G$2:$G$221, K$1), SUMIFS(MRP!$K$2:$K$221, MRP!$B$2:$B$221, $C8, MRP!$G$2:$G$221, K$1), SUMIFS(MRP!$L$2:$L$221, MRP!$B$2:$B$221, $C8, MRP!$G$2:$G$221, K$1) )*F8 -> 0 | L8: =TRIM(Tabla3[[#This Row],[CodInternoArti]]) -> 17030001A
A9: =IF(ISNUMBER(_xlfn.XMATCH(Tabla3[[#This Row],[CodInternoArti]],'Tabla Articulos'!B:B)),"OK","NO ESTA") -> OK | B9: =IF(ISNUMBER(_xlfn.XMATCH('Calcular necesidad'!E:E,'Necesidad por familia'!A:A)),"OK","NO ESTA") -> OK | C9: 16204003A | D9: ROLLO BOLSA ARRANQUE 40 x 60 | E9: =_xlfn.XLOOKUP(C9,'Tabla Articulos'!B:B,'Tabla Articulos'!D:D) -> ARRANQUE 40X60 | F9: =_xlfn.XLOOKUP(C9,'Tabla Articulos'!B:B,'Tabla Articulos'!E:E) -> 1 | G9: =SUM( SUMIFS(MRP!$H$2:$H$221, MRP!$B$2:$B$221, $C9, MRP!$G$2:$G$221, G$1), SUMIFS(MRP!$I$2:$I$221, MRP!$B$2:$B$221, $C9, MRP!$G$2:$G$221, G$1), SUMIFS(MRP!$J$2:$J$221, MRP!$B$2:$B$221, $C9, MRP!$G$2:$G$221, G$1), SUMIFS(MRP!$K$2:$K$221, MRP!$B$2:$B$221, $C9, MRP!$G$2:$G$221, G$1), SUMIFS(MRP!$L$2:$L$221, MRP!$B$2:$B$221, $C9, MRP!$G$2:$G$221, G$1) )*F9 -> 0 | H9: =SUM( SUMIFS(MRP!$H$2:$H$221, MRP!$B$2:$B$221, $C9, MRP!$G$2:$G$221, H$1), SUMIFS(MRP!$I$2:$I$221, MRP!$B$2:$B$221, $C9, MRP!$G$2:$G$221, H$1), SUMIFS(MRP!$J$2:$J$221, MRP!$B$2:$B$221, $C9, MRP!$G$2:$G$221, H$1), SUMIFS(MRP!$K$2:$K$221, MRP!$B$2:$B$221, $C9, MRP!$G$2:$G$221, H$1), SUMIFS(MRP!$L$2:$L$221, MRP!$B$2:$B$221, $C9, MRP!$G$2:$G$221, H$1) )*F9 -> 83 | I9: =SUM( SUMIFS(MRP!$H$2:$H$221, MRP!$B$2:$B$221, $C9, MRP!$G$2:$G$221, I$1), SUMIFS(MRP!$I$2:$I$221, MRP!$B$2:$B$221, $C9, MRP!$G$2:$G$221, I$1), SUMIFS(MRP!$J$2:$J$221, MRP!$B$2:$B$221, $C9, MRP!$G$2:$G$221, I$1), SUMIFS(MRP!$K$2:$K$221, MRP!$B$2:$B$221, $C9, MRP!$G$2:$G$221, I$1), SUMIFS(MRP!$L$2:$L$221, MRP!$B$2:$B$221, $C9, MRP!$G$2:$G$221, I$1) )*F9 -> 0 | J9: =SUM( SUMIFS(MRP!$H$2:$H$221, MRP!$B$2:$B$221, $C9, MRP!$G$2:$G$221, J$1), SUMIFS(MRP!$I$2:$I$221, MRP!$B$2:$B$221, $C9, MRP!$G$2:$G$221, J$1), SUMIFS(MRP!$J$2:$J$221, MRP!$B$2:$B$221, $C9, MRP!$G$2:$G$221, J$1), SUMIFS(MRP!$K$2:$K$221, MRP!$B$2:$B$221, $C9, MRP!$G$2:$G$221, J$1), SUMIFS(MRP!$L$2:$L$221, MRP!$B$2:$B$221, $C9, MRP!$G$2:$G$221, J$1) )*F9 -> 0 | K9: =SUM( SUMIFS(MRP!$H$2:$H$221, MRP!$B$2:$B$221, $C9, MRP!$G$2:$G$221, K$1), SUMIFS(MRP!$I$2:$I$221, MRP!$B$2:$B$221, $C9, MRP!$G$2:$G$221, K$1), SUMIFS(MRP!$J$2:$J$221, MRP!$B$2:$B$221, $C9, MRP!$G$2:$G$221, K$1), SUMIFS(MRP!$K$2:$K$221, MRP!$B$2:$B$221, $C9, MRP!$G$2:$G$221, K$1), SUMIFS(MRP!$L$2:$L$221, MRP!$B$2:$B$221, $C9, MRP!$G$2:$G$221, K$1) )*F9 -> 0 | L9: =TRIM(Tabla3[[#This Row],[CodInternoArti]]) -> 16204003A
A10: =IF(ISNUMBER(_xlfn.XMATCH(Tabla3[[#This Row],[CodInternoArti]],'Tabla Articulos'!B:B)),"OK","NO ESTA") -> OK | B10: =IF(ISNUMBER(_xlfn.XMATCH('Calcular necesidad'!E:E,'Necesidad por familia'!A:A)),"OK","NO ESTA") -> OK | C10: 13072000A | D10: FOLEX 20CMX25XCM XKG | E10: =_xlfn.XLOOKUP(C10,'Tabla Articulos'!B:B,'Tabla Articulos'!D:D) -> FOLEX | F10: =_xlfn.XLOOKUP(C10,'Tabla Articulos'!B:B,'Tabla Articulos'!E:E) -> 1 | G10: =SUM( SUMIFS(MRP!$H$2:$H$221, MRP!$B$2:$B$221, $C10, MRP!$G$2:$G$221, G$1), SUMIFS(MRP!$I$2:$I$221, MRP!$B$2:$B$221, $C10, MRP!$G$2:$G$221, G$1), SUMIFS(MRP!$J$2:$J$221, MRP!$B$2:$B$221, $C10, MRP!$G$2:$G$221, G$1), SUMIFS(MRP!$K$2:$K$221, MRP!$B$2:$B$221, $C10, MRP!$G$2:$G$221, G$1), SUMIFS(MRP!$L$2:$L$221, MRP!$B$2:$B$221, $C10, MRP!$G$2:$G$221, G$1) )*F10 -> 0 | H10: =SUM( SUMIFS(MRP!$H$2:$H$221, MRP!$B$2:$B$221, $C10, MRP!$G$2:$G$221, H$1), SUMIFS(MRP!$I$2:$I$221, MRP!$B$2:$B$221, $C10, MRP!$G$2:$G$221, H$1), SUMIFS(MRP!$J$2:$J$221, MRP!$B$2:$B$221, $C10, MRP!$G$2:$G$221, H$1), SUMIFS(MRP!$K$2:$K$221, MRP!$B$2:$B$221, $C10, MRP!$G$2:$G$221, H$1), SUMIFS(MRP!$L$2:$L$221, MRP!$B$2:$B$221, $C10, MRP!$G$2:$G$221, H$1) )*F10 -> 6 | I10: =SUM( SUMIFS(MRP!$H$2:$H$221, MRP!$B$2:$B$221, $C10, MRP!$G$2:$G$221, I$1), SUMIFS(MRP!$I$2:$I$221, MRP!$B$2:$B$221, $C10, MRP!$G$2:$G$221, I$1), SUMIFS(MRP!$J$2:$J$221, MRP!$B$2:$B$221, $C10, MRP!$G$2:$G$221, I$1), SUMIFS(MRP!$K$2:$K$221, MRP!$B$2:$B$221, $C10, MRP!$G$2:$G$221, I$1), SUMIFS(MRP!$L$2:$L$221, MRP!$B$2:$B$221, $C10, MRP!$G$2:$G$221, I$1) )*F10 -> 0 | J10: =SUM( SUMIFS(MRP!$H$2:$H$221, MRP!$B$2:$B$221, $C10, MRP!$G$2:$G$221, J$1), SUMIFS(MRP!$I$2:$I$221, MRP!$B$2:$B$221, $C10, MRP!$G$2:$G$221, J$1), SUMIFS(MRP!$J$2:$J$221, MRP!$B$2:$B$221, $C10, MRP!$G$2:$G$221, J$1), SUMIFS(MRP!$K$2:$K$221, MRP!$B$2:$B$221, $C10, MRP!$G$2:$G$221, J$1), SUMIFS(MRP!$L$2:$L$221, MRP!$B$2:$B$221, $C10, MRP!$G$2:$G$221, J$1) )*F10 -> 0 | K10: =SUM( SUMIFS(MRP!$H$2:$H$221, MRP!$B$2:$B$221, $C10, MRP!$G$2:$G$221, K$1), SUMIFS(MRP!$I$2:$I$221, MRP!$B$2:$B$221, $C10, MRP!$G$2:$G$221, K$1), SUMIFS(MRP!$J$2:$J$221, MRP!$B$2:$B$221, $C10, MRP!$G$2:$G$221, K$1), SUMIFS(MRP!$K$2:$K$221, MRP!$B$2:$B$221, $C10, MRP!$G$2:$G$221, K$1), SUMIFS(MRP!$L$2:$L$221, MRP!$B$2:$B$221, $C10, MRP!$G$2:$G$221, K$1) )*F10 -> 0 | L10: =TRIM(Tabla3[[#This Row],[CodInternoArti]]) -> 13072000A
A11: =IF(ISNUMBER(_xlfn.XMATCH(Tabla3[[#This Row],[CodInternoArti]],'Tabla Articulos'!B:B)),"OK","NO ESTA") -> OK | B11: =IF(ISNUMBER(_xlfn.XMATCH('Calcular necesidad'!E:E,'Necesidad por familia'!A:A)),"OK","NO ESTA") -> OK | C11: 14004000A | D11: BARBIJOS x 25 UNID | E11: =_xlfn.XLOOKUP(C11,'Tabla Articulos'!B:B,'Tabla Articulos'!D:D) -> BARBIJO QUIRURGICO | F11: =_xlfn.XLOOKUP(C11,'Tabla Articulos'!B:B,'Tabla Articulos'!E:E) -> 25 | G11: =SUM( SUMIFS(MRP!$H$2:$H$221, MRP!$B$2:$B$221, $C11, MRP!$G$2:$G$221, G$1), SUMIFS(MRP!$I$2:$I$221, MRP!$B$2:$B$221, $C11, MRP!$G$2:$G$221, G$1), SUMIFS(MRP!$J$2:$J$221, MRP!$B$2:$B$221, $C11, MRP!$G$2:$G$221, G$1), SUMIFS(MRP!$K$2:$K$221, MRP!$B$2:$B$221, $C11, MRP!$G$2:$G$221, G$1), SUMIFS(MRP!$L$2:$L$221, MRP!$B$2:$B$221, $C11, MRP!$G$2:$G$221, G$1) )*F11 -> 0 | H11: =SUM( SUMIFS(MRP!$H$2:$H$221, MRP!$B$2:$B$221, $C11, MRP!$G$2:$G$221, H$1), SUMIFS(MRP!$I$2:$I$221, MRP!$B$2:$B$221, $C11, MRP!$G$2:$G$221, H$1), SUMIFS(MRP!$J$2:$J$221, MRP!$B$2:$B$221, $C11, MRP!$G$2:$G$221, H$1), SUMIFS(MRP!$K$2:$K$221, MRP!$B$2:$B$221, $C11, MRP!$G$2:$G$221, H$1), SUMIFS(MRP!$L$2:$L$221, MRP!$B$2:$B$221, $C11, MRP!$G$2:$G$221, H$1) )*F11 -> 1175 | I11: =SUM( SUMIFS(MRP!$H$2:$H$221, MRP!$B$2:$B$221, $C11, MRP!$G$2:$G$221, I$1), SUMIFS(MRP!$I$2:$I$221, MRP!$B$2:$B$221, $C11, MRP!$G$2:$G$221, I$1), SUMIFS(MRP!$J$2:$J$221, MRP!$B$2:$B$221, $C11, MRP!$G$2:$G$221, I$1), SUMIFS(MRP!$K$2:$K$221, MRP!$B$2:$B$221, $C11, MRP!$G$2:$G$221, I$1), SUMIFS(MRP!$L$2:$L$221, MRP!$B$2:$B$221, $C11, MRP!$G$2:$G$221, I$1) )*F11 -> 0 | J11: =SUM( SUMIFS(MRP!$H$2:$H$221, MRP!$B$2:$B$221, $C11, MRP!$G$2:$G$221, J$1), SUMIFS(MRP!$I$2:$I$221, MRP!$B$2:$B$221, $C11, MRP!$G$2:$G$221, J$1), SUMIFS(MRP!$J$2:$J$221, MRP!$B$2:$B$221, $C11, MRP!$G$2:$G$221, J$1), SUMIFS(MRP!$K$2:$K$221, MRP!$B$2:$B$221, $C11, MRP!$G$2:$G$221, J$1), SUMIFS(MRP!$L$2:$L$221, MRP!$B$2:$B$221, $C11, MRP!$G$2:$G$221, J$1) )*F11 -> 0 | K11: =SUM( SUMIFS(MRP!$H$2:$H$221, MRP!$B$2:$B$221, $C11, MRP!$G$2:$G$221, K$1), SUMIFS(MRP!$I$2:$I$221, MRP!$B$2:$B$221, $C11, MRP!$G$2:$G$221, K$1), SUMIFS(MRP!$J$2:$J$221, MRP!$B$2:$B$221, $C11, MRP!$G$2:$G$221, K$1), SUMIFS(MRP!$K$2:$K$221, MRP!$B$2:$B$221, $C11, MRP!$G$2:$G$221, K$1), SUMIFS(MRP!$L$2:$L$221, MRP!$B$2:$B$221, $C11, MRP!$G$2:$G$221, K$1) )*F11 -> 0 | L11: =TRIM(Tabla3[[#This Row],[CodInternoArti]]) -> 14004000A
A12: =IF(ISNUMBER(_xlfn.XMATCH(Tabla3[[#This Row],[CodInternoArti]],'Tabla Articulos'!B:B)),"OK","NO ESTA") -> OK | B12: =IF(ISNUMBER(_xlfn.XMATCH('Calcular necesidad'!E:E,'Necesidad por familia'!A:A)),"OK","NO ESTA") -> OK | C12: 16204005A | D12: ROLLO BOLSA ARRANQUE 25X35 | E12: =_xlfn.XLOOKUP(C12,'Tabla Articulos'!B:B,'Tabla Articulos'!D:D) -> ARRANQUE 20X30 | F12: =_xlfn.XLOOKUP(C12,'Tabla Articulos'!B:B,'Tabla Articulos'!E:E) -> 1 | G12: =SUM( SUMIFS(MRP!$H$2:$H$221, MRP!$B$2:$B$221, $C12, MRP!$G$2:$G$221, G$1), SUMIFS(MRP!$I$2:$I$221, MRP!$B$2:$B$221, $C12, MRP!$G$2:$G$221, G$1), SUMIFS(MRP!$J$2:$J$221, MRP!$B$2:$B$221, $C12, MRP!$G$2:$G$221, G$1), SUMIFS(MRP!$K$2:$K$221, MRP!$B$2:$B$221, $C12, MRP!$G$2:$G$221, G$1), SUMIFS(MRP!$L$2:$L$221, MRP!$B$2:$B$221, $C12, MRP!$G$2:$G$221, G$1) )*F12 -> 0 | H12: =SUM( SUMIFS(MRP!$H$2:$H$221, MRP!$B$2:$B$221, $C12, MRP!$G$2:$G$221, H$1), SUMIFS(MRP!$I$2:$I$221, MRP!$B$2:$B$221, $C12, MRP!$G$2:$G$221, H$1), SUMIFS(MRP!$J$2:$J$221, MRP!$B$2:$B$221, $C12, MRP!$G$2:$G$221, H$1), SUMIFS(MRP!$K$2:$K$221, MRP!$B$2:$B$221, $C12, MRP!$G$2:$G$221, H$1), SUMIFS(MRP!$L$2:$L$221, MRP!$B$2:$B$221, $C12, MRP!$G$2:$G$221, H$1) )*F12 -> 75 | I12: =SUM( SUMIFS(MRP!$H$2:$H$221, MRP!$B$2:$B$221, $C12, MRP!$G$2:$G$221, I$1), SUMIFS(MRP!$I$2:$I$221, MRP!$B$2:$B$221, $C12, MRP!$G$2:$G$221, I$1), SUMIFS(MRP!$J$2:$J$221, MRP!$B$2:$B$221, $C12, MRP!$G$2:$G$221, I$1), SUMIFS(MRP!$K$2:$K$221, MRP!$B$2:$B$221, $C12, MRP!$G$2:$G$221, I$1), SUMIFS(MRP!$L$2:$L$221, MRP!$B$2:$B$221, $C12, MRP!$G$2:$G$221, I$1) )*F12 -> 0 | J12: =SUM( SUMIFS(MRP!$H$2:$H$221, MRP!$B$2:$B$221, $C12, MRP!$G$2:$G$221, J$1), SUMIFS(MRP!$I$2:$I$221, MRP!$B$2:$B$221, $C12, MRP!$G$2:$G$221, J$1), SUMIFS(MRP!$J$2:$J$221, MRP!$B$2:$B$221, $C12, MRP!$G$2:$G$221, J$1), SUMIFS(MRP!$K$2:$K$221, MRP!$B$2:$B$221, $C12, MRP!$G$2:$G$221, J$1), SUMIFS(MRP!$L$2:$L$221, MRP!$B$2:$B$221, $C12, MRP!$G$2:$G$221, J$1) )*F12 -> 0 | K12: =SUM( SUMIFS(MRP!$H$2:$H$221, MRP!$B$2:$B$221, $C12, MRP!$G$2:$G$221, K$1), SUMIFS(MRP!$I$2:$I$221, MRP!$B$2:$B$221, $C12, MRP!$G$2:$G$221, K$1), SUMIFS(MRP!$J$2:$J$221, MRP!$B$2:$B$221, $C12, MRP!$G$2:$G$221, K$1), SUMIFS(MRP!$K$2:$K$221, MRP!$B$2:$B$221, $C12, MRP!$G$2:$G$221, K$1), SUMIFS(MRP!$L$2:$L$221, MRP!$B$2:$B$221, $C12, MRP!$G$2:$G$221, K$1) )*F12 -> 0 | L12: =TRIM(Tabla3[[#This Row],[CodInternoArti]]) -> 16204005A
A13: =IF(ISNUMBER(_xlfn.XMATCH(Tabla3[[#This Row],[CodInternoArti]],'Tabla Articulos'!B:B)),"OK","NO ESTA") -> OK | B13: =IF(ISNUMBER(_xlfn.XMATCH('Calcular necesidad'!E:E,'Necesidad por familia'!A:A)),"OK","NO ESTA") -> OK | C13: 16208000A | D13: ROLLO DE BOLSA DE ARRANQUE 50 x 70 | E13: =_xlfn.XLOOKUP(C13,'Tabla Articulos'!B:B,'Tabla Articulos'!D:D) -> ARRANQUE 50X70 | F13: =_xlfn.XLOOKUP(C13,'Tabla Articulos'!B:B,'Tabla Articulos'!E:E) -> 1 | G13: =SUM( SUMIFS(MRP!$H$2:$H$221, MRP!$B$2:$B$221, $C13, MRP!$G$2:$G$221, G$1), SUMIFS(MRP!$I$2:$I$221, MRP!$B$2:$B$221, $C13, MRP!$G$2:$G$221, G$1), SUMIFS(MRP!$J$2:$J$221, MRP!$B$2:$B$221, $C13, MRP!$G$2:$G$221, G$1), SUMIFS(MRP!$K$2:$K$221, MRP!$B$2:$B$221, $C13, MRP!$G$2:$G$221, G$1), SUMIFS(MRP!$L$2:$L$221, MRP!$B$2:$B$221, $C13, MRP!$G$2:$G$221, G$1) )*F13 -> 0 | H13: =SUM( SUMIFS(MRP!$H$2:$H$221, MRP!$B$2:$B$221, $C13, MRP!$G$2:$G$221, H$1), SUMIFS(MRP!$I$2:$I$221, MRP!$B$2:$B$221, $C13, MRP!$G$2:$G$221, H$1), SUMIFS(MRP!$J$2:$J$221, MRP!$B$2:$B$221, $C13, MRP!$G$2:$G$221, H$1), SUMIFS(MRP!$K$2:$K$221, MRP!$B$2:$B$221, $C13, MRP!$G$2:$G$221, H$1), SUMIFS(MRP!$L$2:$L$221, MRP!$B$2:$B$221, $C13, MRP!$G$2:$G$221, H$1) )*F13 -> 35 | I13: =SUM( SUMIFS(MRP!$H$2:$H$221, MRP!$B$2:$B$221, $C13, MRP!$G$2:$G$221, I$1), SUMIFS(MRP!$I$2:$I$221, MRP!$B$2:$B$221, $C13, MRP!$G$2:$G$221, I$1), SUMIFS(MRP!$J$2:$J$221, MRP!$B$2:$B$221, $C13, MRP!$G$2:$G$221, I$1), SUMIFS(MRP!$K$2:$K$221, MRP!$B$2:$B$221, $C13, MRP!$G$2:$G$221, I$1), SUMIFS(MRP!$L$2:$L$221, MRP!$B$2:$B$221, $C13, MRP!$G$2:$G$221, I$1) )*F13 -> 0 | J13: =SUM( SUMIFS(MRP!$H$2:$H$221, MRP!$B$2:$B$221, $C13, MRP!$G$2:$G$221, J$1), SUMIFS(MRP!$I$2:$I$221, MRP!$B$2:$B$221, $C13, MRP!$G$2:$G$221, J$1), SUMIFS(MRP!$J$2:$J$221, MRP!$B$2:$B$221, $C13, MRP!$G$2:$G$221, J$1), SUMIFS(MRP!$K$2:$K$221, MRP!$B$2:$B$221, $C13, MRP!$G$2:$G$221, J$1), SUMIFS(MRP!$L$2:$L$221, MRP!$B$2:$B$221, $C13, MRP!$G$2:$G$221, J$1) )*F13 -> 0 | K13: =SUM( SUMIFS(MRP!$H$2:$H$221, MRP!$B$2:$B$221, $C13, MRP!$G$2:$G$221, K$1), SUMIFS(MRP!$I$2:$I$221, MRP!$B$2:$B$221, $C13, MRP!$G$2:$G$221, K$1), SUMIFS(MRP!$J$2:$J$221, MRP!$B$2:$B$221, $C13, MRP!$G$2:$G$221, K$1), SUMIFS(MRP!$K$2:$K$221, MRP!$B$2:$B$221, $C13, MRP!$G$2:$G$221, K$1), SUMIFS(MRP!$L$2:$L$221, MRP!$B$2:$B$221, $C13, MRP!$G$2:$G$221, K$1) )*F13 -> 0 | L13: =TRIM(Tabla3[[#This Row],[CodInternoArti]]) -> 16208000A
... A113: =IF(ISNUMBER(_xlfn.XMATCH(Tabla3[[#This Row],[CodInternoArti]],'Tabla Articulos'!B:B)),"OK","NO ESTA") -> OK | B113: =IF(ISNUMBER(_xlfn.XMATCH('Calcular necesidad'!E:E,'Necesidad por familia'!A:A)),"OK","NO ESTA") -> OK | C113: 7790321020533 | D113: SERVILLETA BLANCA 33X33X1000U NUTRIRE | E113: =_xlfn.XLOOKUP(C113,'Tabla Articulos'!B:B,'Tabla Articulos'!D:D) -> SERVILLETA 33X33 NUTRIRE | F113: =_xlfn.XLOOKUP(C113,'Tabla Articulos'!B:B,'Tabla Articulos'!E:E) -> 1000 | G113: =SUM( SUMIFS(MRP!$H$2:$H$221, MRP!$B$2:$B$221, $C113, MRP!$G$2:$G$221, G$1), SUMIFS(MRP!$I$2:$I$221, MRP!$B$2:$B$221, $C113, MRP!$G$2:$G$221, G$1), SUMIFS(MRP!$J$2:$J$221, MRP!$B$2:$B$221, $C113, MRP!$G$2:$G$221, G$1), SUMIFS(MRP!$K$2:$K$221, MRP!$B$2:$B$221, $C113, MRP!$G$2:$G$221, G$1), SUMIFS(MRP!$L$2:$L$221, MRP!$B$2:$B$221, $C113, MRP!$G$2:$G$221, G$1) )*F113 -> 0 | H113: =SUM( SUMIFS(MRP!$H$2:$H$221, MRP!$B$2:$B$221, $C113, MRP!$G$2:$G$221, H$1), SUMIFS(MRP!$I$2:$I$221, MRP!$B$2:$B$221, $C113, MRP!$G$2:$G$221, H$1), SUMIFS(MRP!$J$2:$J$221, MRP!$B$2:$B$221, $C113, MRP!$G$2:$G$221, H$1), SUMIFS(MRP!$K$2:$K$221, MRP!$B$2:$B$221, $C113, MRP!$G$2:$G$221, H$1), SUMIFS(MRP!$L$2:$L$221, MRP!$B$2:$B$221, $C113, MRP!$G$2:$G$221, H$1) )*F113 -> 44000 | I113: =SUM( SUMIFS(MRP!$H$2:$H$221, MRP!$B$2:$B$221, $C113, MRP!$G$2:$G$221, I$1), SUMIFS(MRP!$I$2:$I$221, MRP!$B$2:$B$221, $C113, MRP!$G$2:$G$221, I$1), SUMIFS(MRP!$J$2:$J$221, MRP!$B$2:$B$221, $C113, MRP!$G$2:$G$221, I$1), SUMIFS(MRP!$K$2:$K$221, MRP!$B$2:$B$221, $C113, MRP!$G$2:$G$221, I$1), SUMIFS(MRP!$L$2:$L$221, MRP!$B$2:$B$221, $C113, MRP!$G$2:$G$221, I$1) )*F113 -> 0 | J113: =SUM( SUMIFS(MRP!$H$2:$H$221, MRP!$B$2:$B$221, $C113, MRP!$G$2:$G$221, J$1), SUMIFS(MRP!$I$2:$I$221, MRP!$B$2:$B$221, $C113, MRP!$G$2:$G$221, J$1), SUMIFS(MRP!$J$2:$J$221, MRP!$B$2:$B$221, $C113, MRP!$G$2:$G$221, J$1), SUMIFS(MRP!$K$2:$K$221, MRP!$B$2:$B$221, $C113, MRP!$G$2:$G$221, J$1), SUMIFS(MRP!$L$2:$L$221, MRP!$B$2:$B$221, $C113, MRP!$G$2:$G$221, J$1) )*F113 -> 0 | K113: =SUM( SUMIFS(MRP!$H$2:$H$221, MRP!$B$2:$B$221, $C113, MRP!$G$2:$G$221, K$1), SUMIFS(MRP!$I$2:$I$221, MRP!$B$2:$B$221, $C113, MRP!$G$2:$G$221, K$1), SUMIFS(MRP!$J$2:$J$221, MRP!$B$2:$B$221, $C113, MRP!$G$2:$G$221, K$1), SUMIFS(MRP!$K$2:$K$221, MRP!$B$2:$B$221, $C113, MRP!$G$2:$G$221, K$1), SUMIFS(MRP!$L$2:$L$221, MRP!$B$2:$B$221, $C113, MRP!$G$2:$G$221, K$1) )*F113 -> 0 | L113: =TRIM(Tabla3[[#This Row],[CodInternoArti]]) -> 7790321020533
A114: =IF(ISNUMBER(_xlfn.XMATCH(Tabla3[[#This Row],[CodInternoArti]],'Tabla Articulos'!B:B)),"OK","NO ESTA") -> OK | B114: =IF(ISNUMBER(_xlfn.XMATCH('Calcular necesidad'!E:E,'Necesidad por familia'!A:A)),"OK","NO ESTA") -> OK | C114: 1404700012 | D114: SERVILLETA S/LOGO BCA 14X14 | E114: =_xlfn.XLOOKUP(C114,'Tabla Articulos'!B:B,'Tabla Articulos'!D:D) -> SERVILLETA 30X30 S/LOGO | G114: =SUM( SUMIFS(MRP!$H$2:$H$221, MRP!$B$2:$B$221, $C114, MRP!$G$2:$G$221, G$1), SUMIFS(MRP!$I$2:$I$221, MRP!$B$2:$B$221, $C114, MRP!$G$2:$G$221, G$1), SUMIFS(MRP!$J$2:$J$221, MRP!$B$2:$B$221, $C114, MRP!$G$2:$G$221, G$1), SUMIFS(MRP!$K$2:$K$221, MRP!$B$2:$B$221, $C114, MRP!$G$2:$G$221, G$1), SUMIFS(MRP!$L$2:$L$221, MRP!$B$2:$B$221, $C114, MRP!$G$2:$G$221, G$1) )*F114 -> 0 | H114: =SUM( SUMIFS(MRP!$H$2:$H$221, MRP!$B$2:$B$221, $C114, MRP!$G$2:$G$221, H$1), SUMIFS(MRP!$I$2:$I$221, MRP!$B$2:$B$221, $C114, MRP!$G$2:$G$221, H$1), SUMIFS(MRP!$J$2:$J$221, MRP!$B$2:$B$221, $C114, MRP!$G$2:$G$221, H$1), SUMIFS(MRP!$K$2:$K$221, MRP!$B$2:$B$221, $C114, MRP!$G$2:$G$221, H$1), SUMIFS(MRP!$L$2:$L$221, MRP!$B$2:$B$221, $C114, MRP!$G$2:$G$221, H$1) )*F114 -> 0 | I114: =SUM( SUMIFS(MRP!$H$2:$H$221, MRP!$B$2:$B$221, $C114, MRP!$G$2:$G$221, I$1), SUMIFS(MRP!$I$2:$I$221, MRP!$B$2:$B$221, $C114, MRP!$G$2:$G$221, I$1), SUMIFS(MRP!$J$2:$J$221, MRP!$B$2:$B$221, $C114, MRP!$G$2:$G$221, I$1), SUMIFS(MRP!$K$2:$K$221, MRP!$B$2:$B$221, $C114, MRP!$G$2:$G$221, I$1), SUMIFS(MRP!$L$2:$L$221, MRP!$B$2:$B$221, $C114, MRP!$G$2:$G$221, I$1) )*F114 -> 0 | J114: =SUM( SUMIFS(MRP!$H$2:$H$221, MRP!$B$2:$B$221, $C114, MRP!$G$2:$G$221, J$1), SUMIFS(MRP!$I$2:$I$221, MRP!$B$2:$B$221, $C114, MRP!$G$2:$G$221, J$1), SUMIFS(MRP!$J$2:$J$221, MRP!$B$2:$B$221, $C114, MRP!$G$2:$G$221, J$1), SUMIFS(MRP!$K$2:$K$221, MRP!$B$2:$B$221, $C114, MRP!$G$2:$G$221, J$1), SUMIFS(MRP!$L$2:$L$221, MRP!$B$2:$B$221, $C114, MRP!$G$2:$G$221, J$1) )*F114 -> 0 | K114: =SUM( SUMIFS(MRP!$H$2:$H$221, MRP!$B$2:$B$221, $C114, MRP!$G$2:$G$221, K$1), SUMIFS(MRP!$I$2:$I$221, MRP!$B$2:$B$221, $C114, MRP!$G$2:$G$221, K$1), SUMIFS(MRP!$J$2:$J$221, MRP!$B$2:$B$221, $C114, MRP!$G$2:$G$221, K$1), SUMIFS(MRP!$K$2:$K$221, MRP!$B$2:$B$221, $C114, MRP!$G$2:$G$221, K$1), SUMIFS(MRP!$L$2:$L$221, MRP!$B$2:$B$221, $C114, MRP!$G$2:$G$221, K$1) )*F114 -> 0 | L114: =TRIM(Tabla3[[#This Row],[CodInternoArti]]) -> 1404700012
A115: =IF(ISNUMBER(_xlfn.XMATCH(Tabla3[[#This Row],[CodInternoArti]],'Tabla Articulos'!B:B)),"OK","NO ESTA") -> OK | B115: =IF(ISNUMBER(_xlfn.XMATCH('Calcular necesidad'!E:E,'Necesidad por familia'!A:A)),"OK","NO ESTA") -> OK | C115: 7791337118101 | D115: GUANTE LATEX GRANDE X100U NIPRO | E115: =_xlfn.XLOOKUP(C115,'Tabla Articulos'!B:B,'Tabla Articulos'!D:D) -> GUANTE LATEX L | F115: 100 | G115: =SUM( SUMIFS(MRP!$H$2:$H$221, MRP!$B$2:$B$221, $C115, MRP!$G$2:$G$221, G$1), SUMIFS(MRP!$I$2:$I$221, MRP!$B$2:$B$221, $C115, MRP!$G$2:$G$221, G$1), SUMIFS(MRP!$J$2:$J$221, MRP!$B$2:$B$221, $C115, MRP!$G$2:$G$221, G$1), SUMIFS(MRP!$K$2:$K$221, MRP!$B$2:$B$221, $C115, MRP!$G$2:$G$221, G$1), SUMIFS(MRP!$L$2:$L$221, MRP!$B$2:$B$221, $C115, MRP!$G$2:$G$221, G$1) )*F115 -> 0 | H115: =SUM( SUMIFS(MRP!$H$2:$H$221, MRP!$B$2:$B$221, $C115, MRP!$G$2:$G$221, H$1), SUMIFS(MRP!$I$2:$I$221, MRP!$B$2:$B$221, $C115, MRP!$G$2:$G$221, H$1), SUMIFS(MRP!$J$2:$J$221, MRP!$B$2:$B$221, $C115, MRP!$G$2:$G$221, H$1), SUMIFS(MRP!$K$2:$K$221, MRP!$B$2:$B$221, $C115, MRP!$G$2:$G$221, H$1), SUMIFS(MRP!$L$2:$L$221, MRP!$B$2:$B$221, $C115, MRP!$G$2:$G$221, H$1) )*F115 -> 0 | I115: =SUM( SUMIFS(MRP!$H$2:$H$221, MRP!$B$2:$B$221, $C115, MRP!$G$2:$G$221, I$1), SUMIFS(MRP!$I$2:$I$221, MRP!$B$2:$B$221, $C115, MRP!$G$2:$G$221, I$1), SUMIFS(MRP!$J$2:$J$221, MRP!$B$2:$B$221, $C115, MRP!$G$2:$G$221, I$1), SUMIFS(MRP!$K$2:$K$221, MRP!$B$2:$B$221, $C115, MRP!$G$2:$G$221, I$1), SUMIFS(MRP!$L$2:$L$221, MRP!$B$2:$B$221, $C115, MRP!$G$2:$G$221, I$1) )*F115 -> 0 | J115: =SUM( SUMIFS(MRP!$H$2:$H$221, MRP!$B$2:$B$221, $C115, MRP!$G$2:$G$221, J$1), SUMIFS(MRP!$I$2:$I$221, MRP!$B$2:$B$221, $C115, MRP!$G$2:$G$221, J$1), SUMIFS(MRP!$J$2:$J$221, MRP!$B$2:$B$221, $C115, MRP!$G$2:$G$221, J$1), SUMIFS(MRP!$K$2:$K$221, MRP!$B$2:$B$221, $C115, MRP!$G$2:$G$221, J$1), SUMIFS(MRP!$L$2:$L$221, MRP!$B$2:$B$221, $C115, MRP!$G$2:$G$221, J$1) )*F115 -> 0 | K115: =SUM( SUMIFS(MRP!$H$2:$H$221, MRP!$B$2:$B$221, $C115, MRP!$G$2:$G$221, K$1), SUMIFS(MRP!$I$2:$I$221, MRP!$B$2:$B$221, $C115, MRP!$G$2:$G$221, K$1), SUMIFS(MRP!$J$2:$J$221, MRP!$B$2:$B$221, $C115, MRP!$G$2:$G$221, K$1), SUMIFS(MRP!$K$2:$K$221, MRP!$B$2:$B$221, $C115, MRP!$G$2:$G$221, K$1), SUMIFS(MRP!$L$2:$L$221, MRP!$B$2:$B$221, $C115, MRP!$G$2:$G$221, K$1) )*F115 -> 0 | L115: =TRIM(Tabla3[[#This Row],[CodInternoArti]]) -> 7791337118101
A116: =IF(ISNUMBER(_xlfn.XMATCH(Tabla3[[#This Row],[CodInternoArti]],'Tabla Articulos'!B:B)),"OK","NO ESTA") -> OK | B116: =IF(ISNUMBER(_xlfn.XMATCH('Calcular necesidad'!E:E,'Necesidad por familia'!A:A)),"OK","NO ESTA") -> OK | C116: 7790321020393 | D116: VASO CRISTAL 325CCX800U | E116: =_xlfn.XLOOKUP(C116,'Tabla Articulos'!B:B,'Tabla Articulos'!D:D) -> VASO CRISTAL 325 | F116: 800 | G116: =SUM( SUMIFS(MRP!$H$2:$H$221, MRP!$B$2:$B$221, $C116, MRP!$G$2:$G$221, G$1), SUMIFS(MRP!$I$2:$I$221, MRP!$B$2:$B$221, $C116, MRP!$G$2:$G$221, G$1), SUMIFS(MRP!$J$2:$J$221, MRP!$B$2:$B$221, $C116, MRP!$G$2:$G$221, G$1), SUMIFS(MRP!$K$2:$K$221, MRP!$B$2:$B$221, $C116, MRP!$G$2:$G$221, G$1), SUMIFS(MRP!$L$2:$L$221, MRP!$B$2:$B$221, $C116, MRP!$G$2:$G$221, G$1) )*F116 -> 0 | H116: =SUM( SUMIFS(MRP!$H$2:$H$221, MRP!$B$2:$B$221, $C116, MRP!$G$2:$G$221, H$1), SUMIFS(MRP!$I$2:$I$221, MRP!$B$2:$B$221, $C116, MRP!$G$2:$G$221, H$1), SUMIFS(MRP!$J$2:$J$221, MRP!$B$2:$B$221, $C116, MRP!$G$2:$G$221, H$1), SUMIFS(MRP!$K$2:$K$221, MRP!$B$2:$B$221, $C116, MRP!$G$2:$G$221, H$1), SUMIFS(MRP!$L$2:$L$221, MRP!$B$2:$B$221, $C116, MRP!$G$2:$G$221, H$1) )*F116 -> 7200 | I116: =SUM( SUMIFS(MRP!$H$2:$H$221, MRP!$B$2:$B$221, $C116, MRP!$G$2:$G$221, I$1), SUMIFS(MRP!$I$2:$I$221, MRP!$B$2:$B$221, $C116, MRP!$G$2:$G$221, I$1), SUMIFS(MRP!$J$2:$J$221, MRP!$B$2:$B$221, $C116, MRP!$G$2:$G$221, I$1), SUMIFS(MRP!$K$2:$K$221, MRP!$B$2:$B$221, $C116, MRP!$G$2:$G$221, I$1), SUMIFS(MRP!$L$2:$L$221, MRP!$B$2:$B$221, $C116, MRP!$G$2:$G$221, I$1) )*F116 -> 0 | J116: =SUM( SUMIFS(MRP!$H$2:$H$221, MRP!$B$2:$B$221, $C116, MRP!$G$2:$G$221, J$1), SUMIFS(MRP!$I$2:$I$221, MRP!$B$2:$B$221, $C116, MRP!$G$2:$G$221, J$1), SUMIFS(MRP!$J$2:$J$221, MRP!$B$2:$B$221, $C116, MRP!$G$2:$G$221, J$1), SUMIFS(MRP!$K$2:$K$221, MRP!$B$2:$B$221, $C116, MRP!$G$2:$G$221, J$1), SUMIFS(MRP!$L$2:$L$221, MRP!$B$2:$B$221, $C116, MRP!$G$2:$G$221, J$1) )*F116 -> 0 | K116: =SUM( SUMIFS(MRP!$H$2:$H$221, MRP!$B$2:$B$221, $C116, MRP!$G$2:$G$221, K$1), SUMIFS(MRP!$I$2:$I$221, MRP!$B$2:$B$221, $C116, MRP!$G$2:$G$221, K$1), SUMIFS(MRP!$J$2:$J$221, MRP!$B$2:$B$221, $C116, MRP!$G$2:$G$221, K$1), SUMIFS(MRP!$K$2:$K$221, MRP!$B$2:$B$221, $C116, MRP!$G$2:$G$221, K$1), SUMIFS(MRP!$L$2:$L$221, MRP!$B$2:$B$221, $C116, MRP!$G$2:$G$221, K$1) )*F116 -> 0 | L116: =TRIM(Tabla3[[#This Row],[CodInternoArti]]) -> 7790321020393
A117: =IF(ISNUMBER(_xlfn.XMATCH(Tabla3[[#This Row],[CodInternoArti]],'Tabla Articulos'!B:B)),"OK","NO ESTA") -> OK | B117: =IF(ISNUMBER(_xlfn.XMATCH('Calcular necesidad'!E:E,'Necesidad por familia'!A:A)),"OK","NO ESTA") -> OK | C117: 7790321020329 | D117: TAPA VASO TERMICO 240CCX50 | E117: =_xlfn.XLOOKUP(C117,'Tabla Articulos'!B:B,'Tabla Articulos'!D:D) -> TAPA VASO TERMICO 240 | F117: =_xlfn.XLOOKUP(C117,'Tabla Articulos'!B:B,'Tabla Articulos'!E:E) -> 50 | G117: =SUM( SUMIFS(MRP!$H$2:$H$221, MRP!$B$2:$B$221, $C117, MRP!$G$2:$G$221, G$1), SUMIFS(MRP!$I$2:$I$221, MRP!$B$2:$B$221, $C117, MRP!$G$2:$G$221, G$1), SUMIFS(MRP!$J$2:$J$221, MRP!$B$2:$B$221, $C117, MRP!$G$2:$G$221, G$1), SUMIFS(MRP!$K$2:$K$221, MRP!$B$2:$B$221, $C117, MRP!$G$2:$G$221, G$1), SUMIFS(MRP!$L$2:$L$221, MRP!$B$2:$B$221, $C117, MRP!$G$2:$G$221, G$1) )*F117 -> 0 | H117: =SUM( SUMIFS(MRP!$H$2:$H$221, MRP!$B$2:$B$221, $C117, MRP!$G$2:$G$221, H$1), SUMIFS(MRP!$I$2:$I$221, MRP!$B$2:$B$221, $C117, MRP!$G$2:$G$221, H$1), SUMIFS(MRP!$J$2:$J$221, MRP!$B$2:$B$221, $C117, MRP!$G$2:$G$221, H$1), SUMIFS(MRP!$K$2:$K$221, MRP!$B$2:$B$221, $C117, MRP!$G$2:$G$221, H$1), SUMIFS(MRP!$L$2:$L$221, MRP!$B$2:$B$221, $C117, MRP!$G$2:$G$221, H$1) )*F117 -> 17500 | I117: =SUM( SUMIFS(MRP!$H$2:$H$221, MRP!$B$2:$B$221, $C117, MRP!$G$2:$G$221, I$1), SUMIFS(MRP!$I$2:$I$221, MRP!$B$2:$B$221, $C117, MRP!$G$2:$G$221, I$1), SUMIFS(MRP!$J$2:$J$221, MRP!$B$2:$B$221, $C117, MRP!$G$2:$G$221, I$1), SUMIFS(MRP!$K$2:$K$221, MRP!$B$2:$B$221, $C117, MRP!$G$2:$G$221, I$1), SUMIFS(MRP!$L$2:$L$221, MRP!$B$2:$B$221, $C117, MRP!$G$2:$G$221, I$1) )*F117 -> 0 | J117: =SUM( SUMIFS(MRP!$H$2:$H$221, MRP!$B$2:$B$221, $C117, MRP!$G$2:$G$221, J$1), SUMIFS(MRP!$I$2:$I$221, MRP!$B$2:$B$221, $C117, MRP!$G$2:$G$221, J$1), SUMIFS(MRP!$J$2:$J$221, MRP!$B$2:$B$221, $C117, MRP!$G$2:$G$221, J$1), SUMIFS(MRP!$K$2:$K$221, MRP!$B$2:$B$221, $C117, MRP!$G$2:$G$221, J$1), SUMIFS(MRP!$L$2:$L$221, MRP!$B$2:$B$221, $C117, MRP!$G$2:$G$221, J$1) )*F117 -> 0 | K117: =SUM( SUMIFS(MRP!$H$2:$H$221, MRP!$B$2:$B$221, $C117, MRP!$G$2:$G$221, K$1), SUMIFS(MRP!$I$2:$I$221, MRP!$B$2:$B$221, $C117, MRP!$G$2:$G$221, K$1), SUMIFS(MRP!$J$2:$J$221, MRP!$B$2:$B$221, $C117, MRP!$G$2:$G$221, K$1), SUMIFS(MRP!$K$2:$K$221, MRP!$B$2:$B$221, $C117, MRP!$G$2:$G$221, K$1), SUMIFS(MRP!$L$2:$L$221, MRP!$B$2:$B$221, $C117, MRP!$G$2:$G$221, K$1) )*F117 -> 0 | L117: =TRIM(Tabla3[[#This Row],[CodInternoArti]]) -> 7790321020329
