Workbook

Sheet Consumos
A1: EAN | B1: COD SAP | C1: GrpAbr | D1: UM | E1: Familia | F1: Consumo | G1: Consumo total | H1: Ean2 | I1: Esta en necesidad?
A2: 7790000000245 | B2: 2007196 | C2: SERVILLETAS S.MEDICAL 18 X 18 X2000UN | D2: 2000 | E2: SERVILLETAS SWISS 18x18 | F2: 2 | G2: =tabla_consumos[[#This Row],[Consumo]]*tabla_consumos[[#This Row],[UM]] -> 4000 | H2: =TRIM(tabla_consumos[[#This Row],[EAN]]) -> 7790000000245 | I2: =IFERROR(_xlfn.XMATCH(tabla_consumos[[#This Row],[Familia]],Tabla2[Familia],0),"No esta") -> 39
A3: 7795618000094 | B3: 2007210 | C3: ROLLO ARRANQUE 15x20 SONB 290GR X12UN | D3: 12 | E3: ARRANQUE 15x20 | F3: 12 | G3: =tabla_consumos[[#This Row],[Consumo]]*tabla_consumos[[#This Row],[UM]] -> 144 | H3: =TRIM(tabla_consumos[[#This Row],[EAN]]) -> 7795618000094 | I3: =IFERROR(_xlfn.XMATCH(tabla_consumos[[#This Row],[Familia]],Tabla2[Familia],0),"No esta") -> 23
A4: 7795618000193 | B4: 2007209 | C4: ROLLO ARRANQUE 20x25 SONB 750GR X12UN | D4: 12 | E4: ARRANQUE 20x30 | F4: 21 | G4: =tabla_consumos[[#This Row],[Consumo]]*tabla_consumos[[#This Row],[UM]] -> 252 | H4: =TRIM(tabla_consumos[[#This Row],[EAN]]) -> 7795618000193 | I4: =IFERROR(_xlfn.XMATCH(tabla_consumos[[#This Row],[Familia]],Tabla2[Familia],0),"No esta") -> 30
A5: 7790000000253 | B5: 2007140 | C5: VASO MD PLASTIVAS 0,30 LT X100UN | D5: 100 | E5: VASO PLASTICO 300CC | F5: 163 | G5: =tabla_consumos[[#This Row],[Consumo]]*tabla_consumos[[#This Row],[UM]] -> 16300 | H5: =TRIM(tabla_consumos[[#This Row],[EAN]]) -> 7790000000253 | I5: =IFERROR(_xlfn.XMATCH(tabla_consumos[[#This Row],[Familia]],Tabla2[Familia],0),"No esta") -> 18
A6: 9992017900491 | B6: 2007112 | C6: ROLLO ALUM. 28CM 4.2MT 9MIC ALUMAX X1UN | D6: 1 | E6: ROLLO ALUMINIO 40 | F6: 13 | G6: =tabla_consumos[[#This Row],[Consumo]]*tabla_consumos[[#This Row],[UM]] -> 13 | H6: =TRIM(tabla_consumos[[#This Row],[EAN]]) -> 9992017900491 | I6: =IFERROR(_xlfn.XMATCH(tabla_consumos[[#This Row],[Familia]],Tabla2[Familia],0),"No esta") -> 24
A7: 9992017901825 | B7: 2007199 | C7: SERVILLETAS H.BRITANICO 33 X 33 X1000UN | D7: 1000 | E7: SERVILLETAS BRITANICO 33x33 | F7: 85 | G7: =tabla_consumos[[#This Row],[Consumo]]*tabla_consumos[[#This Row],[UM]] -> 85000 | H7: =TRIM(tabla_consumos[[#This Row],[EAN]]) -> 9992017901825 | I7: =IFERROR(_xlfn.XMATCH(tabla_consumos[[#This Row],[Familia]],Tabla2[Familia],0),"No esta") -> 59
A8: 17798038127119 | B8: 2007208 | C8: VASO TERMICO ESTISOL 0.300 LT X1000UN | D8: 1000 | E8: VASO TERMICO 300 | F8: 4 | G8: =tabla_consumos[[#This Row],[Consumo]]*tabla_consumos[[#This Row],[UM]] -> 4000 | H8: =TRIM(tabla_consumos[[#This Row],[EAN]]) -> 17798038127119 | I8: =IFERROR(_xlfn.XMATCH(tabla_consumos[[#This Row],[Familia]],Tabla2[Familia],0),"No esta") -> 27
A9: 7790000000197 | B9: 2007158 | C9: BOLSA CAMISETA BIO.FECULA 40X50 X1500UN | D9: 1500 | E9: BOLSA CAMISETA BIO 40x50 | F9: 3 | G9: =tabla_consumos[[#This Row],[Consumo]]*tabla_consumos[[#This Row],[UM]] -> 4500 | H9: =TRIM(tabla_consumos[[#This Row],[EAN]]) -> 7790000000197 | I9: =IFERROR(_xlfn.XMATCH(tabla_consumos[[#This Row],[Familia]],Tabla2[Familia],0),"No esta") -> 42
A10: 7790000000218 | B10: 2007132 | C10: BOWL COMPOST.17x7 960CC BIO X600UN | D10: 600 | E10: BOWL COMPOSTABLE 960CC | F10: 20 | G10: =tabla_consumos[[#This Row],[Consumo]]*tabla_consumos[[#This Row],[UM]] -> 12000 | H10: =TRIM(tabla_consumos[[#This Row],[EAN]]) -> 7790000000218 | I10: =IFERROR(_xlfn.XMATCH(tabla_consumos[[#This Row],[Familia]],Tabla2[Familia],0),"No esta") -> 19
A11: 7790000000250 | B11: 2007133 | C11: TAPA BOWL COMPOS.17x7 960CC BIO X600UN | D11: 600 | E11: TAPA BOWL COMPOSTABLE 960CC | F11: 12 | G11: =tabla_consumos[[#This Row],[Consumo]]*tabla_consumos[[#This Row],[UM]] -> 7200 | H11: =TRIM(tabla_consumos[[#This Row],[EAN]]) -> 7790000000250 | I11: =IFERROR(_xlfn.XMATCH(tabla_consumos[[#This Row],[Familia]],Tabla2[Familia],0),"No esta") -> 16
A12: 7790000000249 | B12: 2007120 | C12: TAPA BANDEJA 121 MICRO. COTNYL X100UN | D12: 100 | E12: TAPA 101 | F12: 40 | G12: =tabla_consumos[[#This Row],[Consumo]]*tabla_consumos[[#This Row],[UM]] -> 4000 | H12: =TRIM(tabla_consumos[[#This Row],[EAN]]) -> 7790000000249 | I12: =IFERROR(_xlfn.XMATCH(tabla_consumos[[#This Row],[Familia]],Tabla2[Familia],0),"No esta") -> 32
A13: 7790000000192 | B13: 2007115 | C13: BANDEJA 102 RECT. NEGRA COTNYL X100UN | D13: 100 | E13: BANDEJA 102 NEGRA | F13: 185 | G13: =tabla_consumos[[#This Row],[Consumo]]*tabla_consumos[[#This Row],[UM]] -> 18500 | H13: =TRIM(tabla_consumos[[#This Row],[EAN]]) -> 7790000000192 | I13: =IFERROR(_xlfn.XMATCH(tabla_consumos[[#This Row],[Familia]],Tabla2[Familia],0),"No esta") -> 60
... A54: 7790000000198 | B54: 2007142 | C54: BOLSA CAMISETA 40X50X9000UN | D54: 9000 | E54: BOLSA CAMISETA 40X50 | F54: 5 | G54: =tabla_consumos[[#This Row],[Consumo]]*tabla_consumos[[#This Row],[UM]] -> 45000 | H54: =TRIM(tabla_consumos[[#This Row],[EAN]]) -> 7790000000198 | I54: =IFERROR(_xlfn.XMATCH(tabla_consumos[[#This Row],[Familia]],Tabla2[Familia],0),"No esta") -> 36
A55: 7790000000276 | B55: 2007395 | C55: BOLSA CAMISETA BIODEGRADABLE 50X60 | E55: BOLSA CAMISETA BIO 50X60 | F55: 0 | G55: =tabla_consumos[[#This Row],[Consumo]]*tabla_consumos[[#This Row],[UM]] -> 0 | H55: =TRIM(tabla_consumos[[#This Row],[EAN]]) -> 7790000000276 | I55: =IFERROR(_xlfn.XMATCH(tabla_consumos[[#This Row],[Familia]],Tabla2[Familia],0),"No esta") -> 50
A56: 7790021000196 | B56: 2007400 | C56: BOBINA DE ARRANQUE 40X60X12U | D56: 12 | E56: ARRANQUE 40X60 | F56: 5 | G56: =tabla_consumos[[#This Row],[Consumo]]*tabla_consumos[[#This Row],[UM]] -> 60 | H56: =TRIM(tabla_consumos[[#This Row],[EAN]]) -> 7790021000196 | I56: =IFERROR(_xlfn.XMATCH(tabla_consumos[[#This Row],[Familia]],Tabla2[Familia],0),"No esta") -> 34
A57: 7798452810034 | B57: 2011467 | C57: GUANTES LATEX L X100U ALUMAX | D57: 100 | E57: GUANTE LATEX L | F57: 687 | G57: =tabla_consumos[[#This Row],[Consumo]]*tabla_consumos[[#This Row],[UM]] -> 68700 | H57: =TRIM(tabla_consumos[[#This Row],[EAN]]) -> 7798452810034 | I57: =IFERROR(_xlfn.XMATCH(tabla_consumos[[#This Row],[Familia]],Tabla2[Familia],0),"No esta") -> 53
A58: 7798452810027 | B58: 2011468 | C58: GUANTES LATEX M X100U ALUMAX | D58: 100 | E58: GUANTE LATEX M | F58: 899 | G58: =tabla_consumos[[#This Row],[Consumo]]*tabla_consumos[[#This Row],[UM]] -> 89900 | H58: =TRIM(tabla_consumos[[#This Row],[EAN]]) -> 7798452810027 | I58: =IFERROR(_xlfn.XMATCH(tabla_consumos[[#This Row],[Familia]],Tabla2[Familia],0),"No esta") -> 37
A59: 7798098701093 | B59: 2007139 | C59: CUCHARA SUNDAE KOVALPLAS X1000UN | D59: 1000 | E59: CUCHARA SUNDAE | F59: 0 | G59: =tabla_consumos[[#This Row],[Consumo]]*tabla_consumos[[#This Row],[UM]] -> 0 | H59: =TRIM(tabla_consumos[[#This Row],[EAN]]) -> 7798098701093 | I59: =IFERROR(_xlfn.XMATCH(tabla_consumos[[#This Row],[Familia]],Tabla2[Familia],0),"No esta") -> 10
A60: 7798011210053 | B60: 2011502 | C60: BANDEJA 103 MICRO COTNYL X100U | D60: 100 | E60: BANDEJA 103 | F60: 47 | G60: =tabla_consumos[[#This Row],[Consumo]]*tabla_consumos[[#This Row],[UM]] -> 4700 | H60: =TRIM(tabla_consumos[[#This Row],[EAN]]) -> 7798011210053 | I60: =IFERROR(_xlfn.XMATCH(tabla_consumos[[#This Row],[Familia]],Tabla2[Familia],0),"No esta") -> 25
A61: 7798011210060 | B61: 2011503 | C61: TAPA BAND 103 MICRO COTNYL X50UN | D61: 50 | E61: TAPA 103 | F61: 63 | G61: =tabla_consumos[[#This Row],[Consumo]]*tabla_consumos[[#This Row],[UM]] -> 3150 | H61: =TRIM(tabla_consumos[[#This Row],[EAN]]) -> 7798011210060 | I61: =IFERROR(_xlfn.XMATCH(tabla_consumos[[#This Row],[Familia]],Tabla2[Familia],0),"No esta") -> 44
A62: 7798011211043 | B62: 2011474 | C62: BANDEJA 103 X100U MICRO COTNYL | D62: 100 | E62: BANDEJA 103 | F62: 187 | G62: =tabla_consumos[[#This Row],[Consumo]]*tabla_consumos[[#This Row],[UM]] -> 18700 | H62: =TRIM(tabla_consumos[[#This Row],[EAN]]) -> 7798011211043 | I62: =IFERROR(_xlfn.XMATCH(tabla_consumos[[#This Row],[Familia]],Tabla2[Familia],0),"No esta") -> 25
A63: 7790000000702 | B63: 2016491 | C63: GL GUANTES NITRILO X100U ALUMAX | D63: 100 | E63: GUANTE NITRILO M | F63: 83 | G63: =tabla_consumos[[#This Row],[Consumo]]*tabla_consumos[[#This Row],[UM]] -> 8300 | H63: =TRIM(tabla_consumos[[#This Row],[EAN]]) -> 7790000000702 | I63: =IFERROR(_xlfn.XMATCH(tabla_consumos[[#This Row],[Familia]],Tabla2[Familia],0),"No esta") -> 33
A64: 7790250000365 | B64: 2011412 | C64: SERVILLETAS S/H X1000UN ELITE | D64: 1000 | E64: SERVILLETA 30X30 | F64: 51 | G64: =tabla_consumos[[#This Row],[Consumo]]*tabla_consumos[[#This Row],[UM]] -> 51000 | H64: =TRIM(tabla_consumos[[#This Row],[EAN]]) -> 7790250000365 | I64: =IFERROR(_xlfn.XMATCH(tabla_consumos[[#This Row],[Familia]],Tabla2[Familia],0),"No esta") -> 17
A65: 7798011210077 | B65: 2011497 | C65: BANDEJA 105 X100U COTNY | D65: 100 | E65: BANDEJA 105 | F65: 550 | G65: =tabla_consumos[[#This Row],[Consumo]]*tabla_consumos[[#This Row],[UM]] -> 55000 | H65: =TRIM(tabla_consumos[[#This Row],[EAN]]) -> 7798011210077 | I65: =IFERROR(_xlfn.XMATCH(tabla_consumos[[#This Row],[Familia]],Tabla2[Familia],0),"No esta") -> 38
A66: 7798011210039 | B66: 2011504 | C66: GL BANDEJA 102 MICRO COTNYL X100U | D66: 100 | E66: BANDEJA 102 | F66: 106 | G66: =tabla_consumos[[#This Row],[Consumo]]*tabla_consumos[[#This Row],[UM]] -> 10600 | H66: =TRIM(tabla_consumos[[#This Row],[EAN]]) -> 7798011210039 | I66: =IFERROR(_xlfn.XMATCH(tabla_consumos[[#This Row],[Familia]],Tabla2[Familia],0),"No esta") -> 62
A67: 7790000000695 | B67: 2011510 | C67: GL SERVILLETAS SIMIL TELA SWISS X1600U | D67: 1600 | E67: SERVILLETA SWISS MEDICAL | F67: 10 | G67: =tabla_consumos[[#This Row],[Consumo]]*tabla_consumos[[#This Row],[UM]] -> 16000 | H67: =TRIM(tabla_consumos[[#This Row],[EAN]]) -> 7790000000695 | I67: =IFERROR(_xlfn.XMATCH(tabla_consumos[[#This Row],[Familia]],Tabla2[Familia],0),"No esta") -> 9
A68: 7790000000233 | B68: 2007189 | C68: INDIV. GRANDE SWISS MEDICAL X1000UN | D68: 1000 | E68: INDIVIDUAL SWISS MEDICAL | F68: 42 | G68: =tabla_consumos[[#This Row],[Consumo]]*tabla_consumos[[#This Row],[UM]] -> 42000 | H68: =TRIM(tabla_consumos[[#This Row],[EAN]]) -> 7790000000233 | I68: =IFERROR(_xlfn.XMATCH(tabla_consumos[[#This Row],[Familia]],Tabla2[Familia],0),"No esta") -> 6
A69: 7790000000713 | B69: 2016520 | C69: SERV SIMIL TELA S/LOGO X2000U | D69: 2000 | E69: SIMIL TELA S/ LOGO | F69: 0 | G69: =tabla_consumos[[#This Row],[Consumo]]*tabla_consumos[[#This Row],[UM]] -> 0 | H69: =TRIM(tabla_consumos[[#This Row],[EAN]]) -> 7790000000713 | I69: =IFERROR(_xlfn.XMATCH(tabla_consumos[[#This Row],[Familia]],Tabla2[Familia],0),"No esta") -> 54
A70: 9992018107288 | B70: 2007113 | C70: SERVILLETAS S/LOGO BAR. 27X33CM X1000UN | D70: 1000 | E70: SERVILLETA 30X30 | F70: 0 | G70: =tabla_consumos[[#This Row],[Consumo]]*tabla_consumos[[#This Row],[UM]] -> 0 | H70: =TRIM(tabla_consumos[[#This Row],[EAN]]) -> 9992018107288 | I70: =IFERROR(_xlfn.XMATCH(tabla_consumos[[#This Row],[Familia]],Tabla2[Familia],0),"No esta") -> 17
A71: 9992016801782 | B71: 2007114 | C71: SERVILLETAS BARMAN 24X24 CM X2000UN | D71: 2000 | E71: SERVILLETA 30X30 | F71: 8 | G71: =tabla_consumos[[#This Row],[Consumo]]*tabla_consumos[[#This Row],[UM]] -> 16000 | H71: =TRIM(tabla_consumos[[#This Row],[EAN]]) -> 9992016801782 | I71: =IFERROR(_xlfn.XMATCH(tabla_consumos[[#This Row],[Familia]],Tabla2[Familia],0),"No esta") -> 17
A72: 7790000000254 | B72: 2007141 | C72: VASO MD PLASTIVAS 0,33 LT X100UN | D72: 100 | E72: VASO PLASTICO 300CC | F72: 62 | G72: =tabla_consumos[[#This Row],[Consumo]]*tabla_consumos[[#This Row],[UM]] -> 6200 | H72: =TRIM(tabla_consumos[[#This Row],[EAN]]) -> 7790000000254 | I72: =IFERROR(_xlfn.XMATCH(tabla_consumos[[#This Row],[Familia]],Tabla2[Familia],0),"No esta") -> 18
A73: 17798038127096 | B73: 2007386 | C73: GL_VASO TERMICO 180CCX1000U ETISOL | D73: 1000 | E73: VASO TERMICO 180 | F73: 12 | G73: =tabla_consumos[[#This Row],[Consumo]]*tabla_consumos[[#This Row],[UM]] -> 12000 | H73: =TRIM(tabla_consumos[[#This Row],[EAN]]) -> 17798038127096 | I73: =IFERROR(_xlfn.XMATCH(tabla_consumos[[#This Row],[Familia]],Tabla2[Familia],0),"No esta") -> 11
A74: 77896061975324 | B74: 2007152 | C74: SERVI INTER 21X11CM ELITE X18000U | D74: 18000 | E74: SERVILLETAS ELITE 21x11 | F74: 0 | G74: =tabla_consumos[[#This Row],[Consumo]]*tabla_consumos[[#This Row],[UM]] -> 0 | H74: =TRIM(tabla_consumos[[#This Row],[EAN]]) -> 77896061975324 | I74: =IFERROR(_xlfn.XMATCH(tabla_consumos[[#This Row],[Familia]],Tabla2[Familia],0),"No esta") -> 29
A75: 7798188651727 | B75: 2016626 | C75: SERVILLETA S/LOGO 30X30X1000U | D75: 1000 | E75: SERVILLETA 30X30 | F75: 348 | G75: =tabla_consumos[[#This Row],[Consumo]]*tabla_consumos[[#This Row],[UM]] -> 348000 | H75: =TRIM(tabla_consumos[[#This Row],[EAN]]) -> 7798188651727 | I75: =IFERROR(_xlfn.XMATCH(tabla_consumos[[#This Row],[Familia]],Tabla2[Familia],0),"No esta") -> 17
A76: 7790000000707 | B76: 2016498 | C76: SERVILLETA 33X21.5 HEALTH X1000UN | D76: 1000 | E76: SERVILLETA C/ LOGO HEALTH 33X21.5 | F76: 0 | G76: =tabla_consumos[[#This Row],[Consumo]]*tabla_consumos[[#This Row],[UM]] -> 0 | H76: =TRIM(tabla_consumos[[#This Row],[EAN]]) -> 7790000000707 | I76: =IFERROR(_xlfn.XMATCH(tabla_consumos[[#This Row],[Familia]],Tabla2[Familia],0),"No esta") -> 55
A77: 7790000000705 | B77: 2016496 | C77: SERVILLETA 33X21.5 C.GOURMET X1000 | D77: 1000 | E77: SERVILLETA C/ LOGO C. GOURMET 33X21.5 | F77: 35 | G77: =tabla_consumos[[#This Row],[Consumo]]*tabla_consumos[[#This Row],[UM]] -> 35000 | H77: =TRIM(tabla_consumos[[#This Row],[EAN]]) -> 7790000000705 | I77: =IFERROR(_xlfn.XMATCH(tabla_consumos[[#This Row],[Familia]],Tabla2[Familia],0),"No esta") -> 7
A78: 7790000000708 | B78: 2016499 | C78: SERV 33X21.5 BLUE CATTERING X1000UN | D78: 1000 | E78: SERVILLETA C/ LOGO BLUE 33X21.5 | F78: 0 | G78: =tabla_consumos[[#This Row],[Consumo]]*tabla_consumos[[#This Row],[UM]] -> 0 | H78: =TRIM(tabla_consumos[[#This Row],[EAN]]) -> 7790000000708 | I78: =IFERROR(_xlfn.XMATCH(tabla_consumos[[#This Row],[Familia]],Tabla2[Familia],0),"No esta") -> 57
A79: 798011214860 | B79: 2011466 | C79: BANDEJA 101 X100U COTNYL | D79: 100 | E79: BANDEJA 101 | F79: 1299 | G79: =tabla_consumos[[#This Row],[Consumo]]*tabla_consumos[[#This Row],[UM]] -> 129900 | H79: =TRIM(tabla_consumos[[#This Row],[EAN]]) -> 798011214860 | I79: =IFERROR(_xlfn.XMATCH(tabla_consumos[[#This Row],[Familia]],Tabla2[Familia],0),"No esta") -> 3
A80: 0648260488628 | B80: 2007202 | C80: ESCARBADIENTES X500UN | D80: 500 | E80: ESCARBADIENTE | F80: 885 | G80: =tabla_consumos[[#This Row],[Consumo]]*tabla_consumos[[#This Row],[UM]] -> 442500 | H80: =TRIM(tabla_consumos[[#This Row],[EAN]]) -> 0648260488628 | I80: =IFERROR(_xlfn.XMATCH(tabla_consumos[[#This Row],[Familia]],Tabla2[Familia],0),"No esta") -> 21
...

Sheet Stock
A1: Columna1 | B1: CtroDistrib | C1: Empresa | D1: DescrNivelInt5 | E1: Articulo | F1: Material SAP | G1: GrpAbr | H1: UM | I1: Fisico | J1: PendGuardar | K1: NoApto | L1: PedSinOP | M1: PendPreparar | N1: PendImportacion | O1: StockDisp | P1: Ean Normalizado | Q1: Familia | R1: UM producto | S1: Total
A2: 6 | B2: CDM03 - MORENO 3 | C2: SERVICIOS ATLANTICO SA | E2: 7790000000467 | F2: 2007493 | G2: GL_ARMAZON PARA MOPA X100CM | H2: UNIDAD | I2: 11 | J2: 0 | K2: 0 | L2: 0 | M2: 0 | N2: 0 | O2: 11 | P2: =TRIM(Tabla1[[#This Row],[Articulo]]) -> 7790000000467 | Q2: =_xlfn.XLOOKUP(Tabla1[[#This Row],[Ean Normalizado]],tabla_consumos[EAN],tabla_consumos[Familia]) -> #N/A | R2: =_xlfn.XLOOKUP(Tabla1[[#This Row],[Ean Normalizado]],tabla_consumos[EAN],tabla_consumos[UM]) -> #N/A | S2: =Tabla1[[#This Row],[StockDisp]]*Tabla1[[#This Row],[UM producto]] -> #N/A
A3: 6 | B3: CDM03 - MORENO 3 | C3: SERVICIOS ATLANTICO SA | E3: 9992017900491 | F3: 2007112 | G3: ROLLO ALUM. 28CM 4.2MT 9MIC ALUMAX | H3: UNIDAD | I3: 31 | J3: 0 | K3: 0 | L3: 0 | M3: 0 | N3: 0 | O3: 31 | P3: =TRIM(Tabla1[[#This Row],[Articulo]]) -> 9992017900491 | Q3: =_xlfn.XLOOKUP(Tabla1[[#This Row],[Ean Normalizado]],tabla_consumos[EAN],tabla_consumos[Familia]) -> ROLLO ALUMINIO 40 | R3: =_xlfn.XLOOKUP(Tabla1[[#This Row],[Ean Normalizado]],tabla_consumos[EAN],tabla_consumos[UM]) -> 1 | S3: =Tabla1[[#This Row],[StockDisp]]*Tabla1[[#This Row],[UM producto]] -> 31
A4: 6 | B4: CDM03 - MORENO 3 | C4: SERVICIOS ATLANTICO SA | D4: CUCHARAS | E4: 71404111849 | F4: 2016597 | G4: CUCHARA DESC.SUNDAE X1000U | H4: UNIDAD | I4: 124 | J4: 0 | K4: 0 | L4: 0 | M4: 0 | N4: 0 | O4: 124 | P4: =TRIM(Tabla1[[#This Row],[Articulo]]) -> 71404111849 | Q4: =_xlfn.XLOOKUP(Tabla1[[#This Row],[Ean Normalizado]],tabla_consumos[EAN],tabla_consumos[Familia]) -> CUCHARA SUNDAE | R4: =_xlfn.XLOOKUP(Tabla1[[#This Row],[Ean Normalizado]],tabla_consumos[EAN],tabla_consumos[UM]) -> 1000 | S4: =Tabla1[[#This Row],[StockDisp]]*Tabla1[[#This Row],[UM producto]] -> 124000
A5: 6 | B5: CDM03 - MORENO 3 | C5: SERVICIOS ATLANTICO SA | D5: BAND 103 | E5: 7790000000380 | F5: 2007322 | G5: BANDEJA 103 BIODEG. X 900U MARCA PR | H5: UNIDAD | I5: 10 | J5: 0 | K5: 0 | L5: 0 | M5: 0 | N5: 0 | O5: 10 | P5: =TRIM(Tabla1[[#This Row],[Articulo]]) -> 7790000000380 | Q5: =_xlfn.XLOOKUP(Tabla1[[#This Row],[Ean Normalizado]],tabla_consumos[EAN],tabla_consumos[Familia]) -> BANDEJA 103 BIO | R5: =_xlfn.XLOOKUP(Tabla1[[#This Row],[Ean Normalizado]],tabla_consumos[EAN],tabla_consumos[UM]) -> 900 | S5: =Tabla1[[#This Row],[StockDisp]]*Tabla1[[#This Row],[UM producto]] -> 9000
A6: 5 | B6: CDM02 - MORENO 2 | C6: SERVICIOS ATLANTICO SA | D6: TURRON DE MANI CON MIEL | E6: 7790380012108 | F6: 4018805 | G6: TURRON MANI C/ MIEL X120G | H6: UNIDAD | I6: 194 | J6: 0 | K6: 0 | L6: 0 | M6: 0 | N6: 0 | O6: 194 | P6: =TRIM(Tabla1[[#This Row],[Articulo]]) -> 7790380012108 | Q6: =_xlfn.XLOOKUP(Tabla1[[#This Row],[Ean Normalizado]],tabla_consumos[EAN],tabla_consumos[Familia]) -> #N/A | R6: =_xlfn.XLOOKUP(Tabla1[[#This Row],[Ean Normalizado]],tabla_consumos[EAN],tabla_consumos[UM]) -> #N/A | S6: =Tabla1[[#This Row],[StockDisp]]*Tabla1[[#This Row],[UM producto]] -> #N/A
A7: 6 | B7: CDM03 - MORENO 3 | C7: SERVICIOS ATLANTICO SA | E7: 7790000000216 | F7: 2007176 | G7: BOLSA RES. VERD 110X120CM40MIC X50U | H7: UNIDAD | I7: 89 | J7: 0 | K7: 0 | L7: 0 | M7: 0 | N7: 0 | O7: 89 | P7: =TRIM(Tabla1[[#This Row],[Articulo]]) -> 7790000000216 | Q7: =_xlfn.XLOOKUP(Tabla1[[#This Row],[Ean Normalizado]],tabla_consumos[EAN],tabla_consumos[Familia]) -> #N/A | R7: =_xlfn.XLOOKUP(Tabla1[[#This Row],[Ean Normalizado]],tabla_consumos[EAN],tabla_consumos[UM]) -> #N/A | S7: =Tabla1[[#This Row],[StockDisp]]*Tabla1[[#This Row],[UM producto]] -> #N/A
A8: 5 | B8: CDM02 - MORENO 2 | C8: SERVICIOS ATLANTICO SA | D8: MAYONESA INDIVIDUAL | E8: 7798011976591 | F8: 4020499 | G8: MAYONESA IND 8CC X198U ABEDUL | H8: UNIDAD | I8: 16 | J8: 0 | K8: 0 | L8: 0 | M8: 4 | N8: 0 | O8: 12 | P8: =TRIM(Tabla1[[#This Row],[Articulo]]) -> 7798011976591 | Q8: =_xlfn.XLOOKUP(Tabla1[[#This Row],[Ean Normalizado]],tabla_consumos[EAN],tabla_consumos[Familia]) -> #N/A | R8: =_xlfn.XLOOKUP(Tabla1[[#This Row],[Ean Normalizado]],tabla_consumos[EAN],tabla_consumos[UM]) -> #N/A | S8: =Tabla1[[#This Row],[StockDisp]]*Tabla1[[#This Row],[UM producto]] -> #N/A
A9: 6 | B9: CDM03 - MORENO 3 | C9: SERVICIOS ATLANTICO SA | D9: BOLSAS ARRANQUE | E9: 7794459001406 | F9: 2016599 | G9: ROLLO ARRAN. 20 X 25 X12U 750GR | H9: UNIDAD | I9: 4 | J9: 0 | K9: 0 | L9: 0 | M9: 0 | N9: 0 | O9: 4 | P9: =TRIM(Tabla1[[#This Row],[Articulo]]) -> 7794459001406 | Q9: =_xlfn.XLOOKUP(Tabla1[[#This Row],[Ean Normalizado]],tabla_consumos[EAN],tabla_consumos[Familia]) -> #N/A | R9: =_xlfn.XLOOKUP(Tabla1[[#This Row],[Ean Normalizado]],tabla_consumos[EAN],tabla_consumos[UM]) -> #N/A | S9: =Tabla1[[#This Row],[StockDisp]]*Tabla1[[#This Row],[UM producto]] -> #N/A
A10: 6 | B10: CDM03 - MORENO 3 | C10: SERVICIOS ATLANTICO SA | D10: VASO TERMICO | E10: 7790000000472 | F10: 2007498 | G10: GL_VASO TERM 240CCX1000UN ETISOL | H10: UNIDAD | I10: 134 | J10: 54 | K10: 0 | L10: 0 | M10: 1 | N10: 0 | O10: 187 | P10: =TRIM(Tabla1[[#This Row],[Articulo]]) -> 7790000000472 | Q10: =_xlfn.XLOOKUP(Tabla1[[#This Row],[Ean Normalizado]],tabla_consumos[EAN],tabla_consumos[Familia]) -> VASO TERMICO 240 | R10: =_xlfn.XLOOKUP(Tabla1[[#This Row],[Ean Normalizado]],tabla_consumos[EAN],tabla_consumos[UM]) -> 1000 | S10: =Tabla1[[#This Row],[StockDisp]]*Tabla1[[#This Row],[UM producto]] -> 187000
A11: 5 | B11: CDM02 - MORENO 2 | C11: SERVICIOS ATLANTICO SA | D11: ACEITE MAIZ INDIV | E11: 7798011976461 | F11: 4020300 | G11: ACEITE MAIZ 8CC X198U ABEDUL | H11: UNIDAD | I11: 191 | J11: 0 | K11: 0 | L11: 0 | M11: 0 | N11: 0 | O11: 191 | P11: =TRIM(Tabla1[[#This Row],[Articulo]]) -> 7798011976461 | Q11: =_xlfn.XLOOKUP(Tabla1[[#This Row],[Ean Normalizado]],tabla_consumos[EAN],tabla_consumos[Familia]) -> #N/A | R11: =_xlfn.XLOOKUP(Tabla1[[#This Row],[Ean Normalizado]],tabla_consumos[EAN],tabla_consumos[UM]) -> #N/A | S11: =Tabla1[[#This Row],[StockDisp]]*Tabla1[[#This Row],[UM producto]] -> #N/A
A12: 5 | B12: CDM02 - MORENO 2 | C12: SERVICIOS ATLANTICO SA | E12: 4004650 | F12: 4004650 | G12: ZAPALLO KABUTIA KG | H12: Kgs | I12: 48 | J12: 0 | K12: 0 | L12: 0 | M12: 10 | N12: 0 | O12: 38 | P12: =TRIM(Tabla1[[#This Row],[Articulo]]) -> 4004650 | Q12: =_xlfn.XLOOKUP(Tabla1[[#This Row],[Ean Normalizado]],tabla_consumos[EAN],tabla_consumos[Familia]) -> #N/A | R12: =_xlfn.XLOOKUP(Tabla1[[#This Row],[Ean Normalizado]],tabla_consumos[EAN],tabla_consumos[UM]) -> #N/A | S12: =Tabla1[[#This Row],[StockDisp]]*Tabla1[[#This Row],[UM producto]] -> #N/A
A13: 6 | B13: CDM03 - MORENO 3 | C13: SERVICIOS ATLANTICO SA | D13: PAÑO MICROFIBRA | E13: 7790000000461 | F13: 2007484 | G13: GL_PANO MICROF.MULT VERDE CLEANTEX | H13: UNIDAD | I13: 430 | J13: 0 | K13: 0 | L13: 0 | M13: 0 | N13: 0 | O13: 430 | P13: =TRIM(Tabla1[[#This Row],[Articulo]]) -> 7790000000461 | Q13: =_xlfn.XLOOKUP(Tabla1[[#This Row],[Ean Normalizado]],tabla_consumos[EAN],tabla_consumos[Familia]) -> #N/A | R13: =_xlfn.XLOOKUP(Tabla1[[#This Row],[Ean Normalizado]],tabla_consumos[EAN],tabla_consumos[UM]) -> #N/A | S13: =Tabla1[[#This Row],[StockDisp]]*Tabla1[[#This Row],[UM producto]] -> #N/A
A14: 1 | B14: CD MORENO | C14: SERVICIOS ATLANTICO SA | D14: PAN MIGNON SALVADO | E14: 7792590005505 | F14: 4076705 | G14: PAN MIGNON SALVADO CONG X267U | H14: UNIDAD | I14: 108 | J14: 0 | K14: 0 | L14: 0 | M14: 0 | N14: 0 | O14: 108 | P14: =TRIM(Tabla1[[#This Row],[Articulo]]) -> 7792590005505 | Q14: =_xlfn.XLOOKUP(Tabla1[[#This Row],[Ean Normalizado]],tabla_consumos[EAN],tabla_consumos[Familia]) -> #N/A | R14: =_xlfn.XLOOKUP(Tabla1[[#This Row],[Ean Normalizado]],tabla_consumos[EAN],tabla_consumos[UM]) -> #N/A | S14: =Tabla1[[#This Row],[StockDisp]]*Tabla1[[#This Row],[UM producto]] -> #N/A
A15: 6 | B15: CDM03 - MORENO 3 | C15: SERVICIOS ATLANTICO SA | E15: 7790000000207 | F15: 2007167 | G15: BOLSA RES AMARILL 60X90CM30MCX50UN | H15: PALLET | I15: 367 | J15: 0 | K15: 0 | L15: 0 | M15: 0 | N15: 0 | O15: 367 | P15: =TRIM(Tabla1[[#This Row],[Articulo]]) -> 7790000000207 | Q15: =_xlfn.XLOOKUP(Tabla1[[#This Row],[Ean Normalizado]],tabla_consumos[EAN],tabla_consumos[Familia]) -> #N/A | R15: =_xlfn.XLOOKUP(Tabla1[[#This Row],[Ean Normalizado]],tabla_consumos[EAN],tabla_consumos[UM]) -> #N/A | S15: =Tabla1[[#This Row],[StockDisp]]*Tabla1[[#This Row],[UM producto]] -> #N/A
A16: 6 | B16: CDM03 - MORENO 3 | C16: SERVICIOS ATLANTICO SA | D16: SANITIZANTE | E16: 7798332280780 | F16: 2006718 | G16: GL_DESINF LIQ FRU/HORT X5LT SPARCH | H16: UNIDAD | I16: 121 | J16: 0 | K16: 0 | L16: 0 | M16: 8 | N16: 0 | O16: 113 | P16: =TRIM(Tabla1[[#This Row],[Articulo]]) -> 7798332280780 | Q16: =_xlfn.XLOOKUP(Tabla1[[#This Row],[Ean Normalizado]],tabla_consumos[EAN],tabla_consumos[Familia]) -> #N/A | R16: =_xlfn.XLOOKUP(Tabla1[[#This Row],[Ean Normalizado]],tabla_consumos[EAN],tabla_consumos[UM]) -> #N/A | S16: =Tabla1[[#This Row],[StockDisp]]*Tabla1[[#This Row],[UM producto]] -> #N/A
A17: 6 | B17: CDM03 - MORENO 3 | C17: SERVICIOS ATLANTICO SA | E17: 17798038127119 | F17: 2007208 | G17: VASO TERMICO MD ESTISOL 0,3LTX1000U | H17: UNIDAD | I17: 2 | J17: 0 | K17: 0 | L17: 0 | M17: 0 | N17: 0 | O17: 2 | P17: =TRIM(Tabla1[[#This Row],[Articulo]]) -> 17798038127119 | Q17: =_xlfn.XLOOKUP(Tabla1[[#This Row],[Ean Normalizado]],tabla_consumos[EAN],tabla_consumos[Familia]) -> VASO TERMICO 300 | R17: =_xlfn.XLOOKUP(Tabla1[[#This Row],[Ean Normalizado]],tabla_consumos[EAN],tabla_consumos[UM]) -> 1000 | S17: =Tabla1[[#This Row],[StockDisp]]*Tabla1[[#This Row],[UM producto]] -> 2000
A18: 6 | B18: CDM03 - MORENO 3 | C18: SERVICIOS ATLANTICO SA | D18: BOLSA RESIDUO | E18: 7790000000506 | F18: 2007539 | G18: GL_BOLSA RESID BCA 60X90X50UN 30MIC | H18: UNIDAD | I18: 53 | J18: 0 | K18: 0 | L18: 0 | M18: 0 | N18: 0 | O18: 53 | P18: =TRIM(Tabla1[[#This Row],[Articulo]]) -> 7790000000506 | Q18: =_xlfn.XLOOKUP(Tabla1[[#This Row],[Ean Normalizado]],tabla_consumos[EAN],tabla_consumos[Familia]) -> #N/A | R18: =_xlfn.XLOOKUP(Tabla1[[#This Row],[Ean Normalizado]],tabla_consumos[EAN],tabla_consumos[UM]) -> #N/A | S18: =Tabla1[[#This Row],[StockDisp]]*Tabla1[[#This Row],[UM producto]] -> #N/A
A19: 5 | B19: CDM02 - MORENO 2 | C19: SERVICIOS ATLANTICO SA | D19: CEBOLLA | E19: 4001189 | F19: 4001189 | G19: GL CEBOLLON KG | H19: Kgs | I19: 2521.75 | J19: 0 | K19: 0 | L19: 290 | M19: 1525 | N19: 0 | O19: 706.75 | P19: =TRIM(Tabla1[[#This Row],[Articulo]]) -> 4001189 | Q19: =_xlfn.XLOOKUP(Tabla1[[#This Row],[Ean Normalizado]],tabla_consumos[EAN],tabla_consumos[Familia]) -> #N/A | R19: =_xlfn.XLOOKUP(Tabla1[[#This Row],[Ean Normalizado]],tabla_consumos[EAN],tabla_consumos[UM]) -> #N/A | S19: =Tabla1[[#This Row],[StockDisp]]*Tabla1[[#This Row],[UM producto]] -> #N/A
A20: 5 | B20: CDM02 - MORENO 2 | C20: SERVICIOS ATLANTICO SA | E20: 4001201 | F20: 4001201 | G20: LECHUGA CRIOLLA KG | H20: Kgs | I20: 37 | J20: 0 | K20: 0 | L20: 0 | M20: 27 | N20: 0 | O20: 10 | P20: =TRIM(Tabla1[[#This Row],[Articulo]]) -> 4001201 | Q20: =_xlfn.XLOOKUP(Tabla1[[#This Row],[Ean Normalizado]],tabla_consumos[EAN],tabla_consumos[Familia]) -> #N/A | R20: =_xlfn.XLOOKUP(Tabla1[[#This Row],[Ean Normalizado]],tabla_consumos[EAN],tabla_consumos[UM]) -> #N/A | S20: =Tabla1[[#This Row],[StockDisp]]*Tabla1[[#This Row],[UM producto]] -> #N/A
A21: 6 | B21: CDM03 - MORENO 3 | C21: SERVICIOS ATLANTICO SA | D21: BOLSA RESIDUO AZUL | E21: 7790000000466 | F21: 2007492 | G21: GL_BOLSAS RESID AZUL 90X110X50UN | H21: UNIDAD | I21: 183 | J21: 0 | K21: 0 | L21: 0 | M21: 0 | N21: 0 | O21: 183 | P21: =TRIM(Tabla1[[#This Row],[Articulo]]) -> 7790000000466 | Q21: =_xlfn.XLOOKUP(Tabla1[[#This Row],[Ean Normalizado]],tabla_consumos[EAN],tabla_consumos[Familia]) -> #N/A | R21: =_xlfn.XLOOKUP(Tabla1[[#This Row],[Ean Normalizado]],tabla_consumos[EAN],tabla_consumos[UM]) -> #N/A | S21: =Tabla1[[#This Row],[StockDisp]]*Tabla1[[#This Row],[UM producto]] -> #N/A
A22: 5 | B22: CDM02 - MORENO 2 | C22: SERVICIOS ATLANTICO SA | E22: 4001213 | F22: 4001213 | G22: PIMIENTO VERDE KG | H22: Kgs | I22: 219.81 | J22: 0 | K22: 0 | L22: 18.5 | M22: 163.5 | N22: 0 | O22: 37.81 | P22: =TRIM(Tabla1[[#This Row],[Articulo]]) -> 4001213 | Q22: =_xlfn.XLOOKUP(Tabla1[[#This Row],[Ean Normalizado]],tabla_consumos[EAN],tabla_consumos[Familia]) -> #N/A | R22: =_xlfn.XLOOKUP(Tabla1[[#This Row],[Ean Normalizado]],tabla_consumos[EAN],tabla_consumos[UM]) -> #N/A | S22: =Tabla1[[#This Row],[StockDisp]]*Tabla1[[#This Row],[UM producto]] -> #N/A
A23: 1 | B23: CD MORENO | C23: SERVICIOS ATLANTICO SA | D23: QUESO BARRA | E23: 7790000000636 | F23: 4024740 | G23: QUESO BARRA MD LA PAULINA KG | H23: Kgs | I23: 1.22 | J23: 0 | K23: 0 | L23: 0 | M23: 0 | N23: 0 | O23: 1.22 | P23: =TRIM(Tabla1[[#This Row],[Articulo]]) -> 7790000000636 | Q23: =_xlfn.XLOOKUP(Tabla1[[#This Row],[Ean Normalizado]],tabla_consumos[EAN],tabla_consumos[Familia]) -> #N/A | R23: =_xlfn.XLOOKUP(Tabla1[[#This Row],[Ean Normalizado]],tabla_consumos[EAN],tabla_consumos[UM]) -> #N/A | S23: =Tabla1[[#This Row],[StockDisp]]*Tabla1[[#This Row],[UM producto]] -> #N/A
A24: 5 | B24: CDM02 - MORENO 2 | C24: SERVICIOS ATLANTICO SA | E24: 4001216 | F24: 4001216 | G24: RADICHETA KG | H24: Kgs | I24: 7.75 | J24: 0 | K24: 0 | L24: 0 | M24: 5.75 | N24: 0 | O24: 2 | P24: =TRIM(Tabla1[[#This Row],[Articulo]]) -> 4001216 | Q24: =_xlfn.XLOOKUP(Tabla1[[#This Row],[Ean Normalizado]],tabla_consumos[EAN],tabla_consumos[Familia]) -> #N/A | R24: =_xlfn.XLOOKUP(Tabla1[[#This Row],[Ean Normalizado]],tabla_consumos[EAN],tabla_consumos[UM]) -> #N/A | S24: =Tabla1[[#This Row],[StockDisp]]*Tabla1[[#This Row],[UM producto]] -> #N/A
A25: 6 | B25: CDM03 - MORENO 3 | C25: SERVICIOS ATLANTICO SA | E25: 7790000000205 | F25: 2007165 | G25: BOLSA PARA CESTO 50X70CM X50UN | H25: UNIDAD | I25: 226 | J25: 0 | K25: 0 | L25: 0 | M25: 0 | N25: 0 | O25: 226 | P25: =TRIM(Tabla1[[#This Row],[Articulo]]) -> 7790000000205 | Q25: =_xlfn.XLOOKUP(Tabla1[[#This Row],[Ean Normalizado]],tabla_consumos[EAN],tabla_consumos[Familia]) -> #N/A | R25: =_xlfn.XLOOKUP(Tabla1[[#This Row],[Ean Normalizado]],tabla_consumos[EAN],tabla_consumos[UM]) -> #N/A | S25: =Tabla1[[#This Row],[StockDisp]]*Tabla1[[#This Row],[UM producto]] -> #N/A
A26: 6 | B26: CDM03 - MORENO 3 | C26: SERVICIOS ATLANTICO SA | D26: BANDEJA 105 CUADRADA | E26: 7790000000381 | F26: 2007323 | G26: BANDEJA 105 BIODEG. X 700UN MARCA P | H26: UNIDAD | I26: 6 | J26: 0 | K26: 0 | L26: 0 | M26: 0 | N26: 0 | O26: 6 | P26: =TRIM(Tabla1[[#This Row],[Articulo]]) -> 7790000000381 | Q26: =_xlfn.XLOOKUP(Tabla1[[#This Row],[Ean Normalizado]],tabla_consumos[EAN],tabla_consumos[Familia]) -> BANDEJA 105 BIO | R26: =_xlfn.XLOOKUP(Tabla1[[#This Row],[Ean Normalizado]],tabla_consumos[EAN],tabla_consumos[UM]) -> 700 | S26: =Tabla1[[#This Row],[StockDisp]]*Tabla1[[#This Row],[UM producto]] -> 4200
A27: 5 | B27: CDM02 - MORENO 2 | C27: SERVICIOS ATLANTICO SA | E27: 4001214 | F27: 4001214 | G27: PUERRO KG | H27: Kgs | I27: 143.5 | J27: 0 | K27: 0 | L27: 26.1 | M27: 83.8 | N27: 0 | O27: 33.6 | P27: =TRIM(Tabla1[[#This Row],[Articulo]]) -> 4001214 | Q27: =_xlfn.XLOOKUP(Tabla1[[#This Row],[Ean Normalizado]],tabla_consumos[EAN],tabla_consumos[Familia]) -> #N/A | R27: =_xlfn.XLOOKUP(Tabla1[[#This Row],[Ean Normalizado]],tabla_consumos[EAN],tabla_consumos[UM]) -> #N/A | S27: =Tabla1[[#This Row],[StockDisp]]*Tabla1[[#This Row],[UM producto]] -> #N/A
A28: 6 | B28: CDM03 - MORENO 3 | C28: SERVICIOS ATLANTICO SA | D28: PAPEL HIGIENICO | E28: 7790250061137 | F28: 2007409 | G28: GL_PAPEL HIG S/H 300MTX4U ELITE | H28: UNIDAD | I28: 66 | J28: 0 | K28: 0 | L28: 0 | M28: 0 | N28: 0 | O28: 66 | P28: =TRIM(Tabla1[[#This Row],[Articulo]]) -> 7790250061137 | Q28: =_xlfn.XLOOKUP(Tabla1[[#This Row],[Ean Normalizado]],tabla_consumos[EAN],tabla_consumos[Familia]) -> #N/A | R28: =_xlfn.XLOOKUP(Tabla1[[#This Row],[Ean Normalizado]],tabla_consumos[EAN],tabla_consumos[UM]) -> #N/A | S28: =Tabla1[[#This Row],[StockDisp]]*Tabla1[[#This Row],[UM producto]] -> #N/A
A29: 6 | B29: CDM03 - MORENO 3 | C29: SERVICIOS ATLANTICO SA | D29: BAND 103 | E29: 7798011211043 | F29: 2011474 | G29: BANDEJA 103 X100U MICRO COTNYL | H29: UNIDAD | I29: 279 | J29: 0 | K29: 0 | L29: 0 | M29: 3 | N29: 0 | O29: 276 | P29: =TRIM(Tabla1[[#This Row],[Articulo]]) -> 7798011211043 | Q29: =_xlfn.XLOOKUP(Tabla1[[#This Row],[Ean Normalizado]],tabla_consumos[EAN],tabla_consumos[Familia]) -> BANDEJA 103 | R29: =_xlfn.XLOOKUP(Tabla1[[#This Row],[Ean Normalizado]],tabla_consumos[EAN],tabla_consumos[UM]) -> 100 | S29: =Tabla1[[#This Row],[StockDisp]]*Tabla1[[#This Row],[UM producto]] -> 27600
A30: 6 | B30: CDM03 - MORENO 3 | C30: SERVICIOS ATLANTICO SA | E30: 7790000000217 | F30: 2007177 | G30: BOLSA RES. 45X60 NEG. 80MIC X 50UN | H30: UNIDAD | I30: 352 | J30: 0 | K30: 0 | L30: 0 | M30: 0 | N30: 0 | O30: 352 | P30: =TRIM(Tabla1[[#This Row],[Articulo]]) -> 7790000000217 | Q30: =_xlfn.XLOOKUP(Tabla1[[#This Row],[Ean Normalizado]],tabla_consumos[EAN],tabla_consumos[Familia]) -> #N/A | R30: =_xlfn.XLOOKUP(Tabla1[[#This Row],[Ean Normalizado]],tabla_consumos[EAN],tabla_consumos[UM]) -> #N/A | S30: =Tabla1[[#This Row],[StockDisp]]*Tabla1[[#This Row],[UM producto]] -> #N/A
A31: 6 | B31: CDM03 - MORENO 3 | C31: SERVICIOS ATLANTICO SA | D31: BOLSA RESIDUO | E31: 7790000000509 | F31: 2007540 | G31: GL_BOLSA CARAM 60X90X50U 30MC MPROP | H31: UNIDAD | I31: 30 | J31: 100 | K31: 0 | L31: 0 | M31: 0 | N31: 0 | O31: 130 | P31: =TRIM(Tabla1[[#This Row],[Articulo]]) -> 7790000000509 | Q31: =_xlfn.XLOOKUP(Tabla1[[#This Row],[Ean Normalizado]],tabla_consumos[EAN],tabla_consumos[Familia]) -> #N/A | R31: =_xlfn.XLOOKUP(Tabla1[[#This Row],[Ean Normalizado]],tabla_consumos[EAN],tabla_consumos[UM]) -> #N/A | S31: =Tabla1[[#This Row],[StockDisp]]*Tabla1[[#This Row],[UM producto]] -> #N/A
A32: 5 | B32: CDM02 - MORENO 2 | C32: SERVICIOS ATLANTICO SA | D32: TE HIERBAS | E32: 7790387001440 | F32: 4077171 | G32: TE TARAGUI MEZCLA HIERBAS 6X20 | H32: UNIDAD | I32: 126 | J32: 0 | K32: 0 | L32: 0 | M32: 0 | N32: 0 | O32: 126 | P32: =TRIM(Tabla1[[#This Row],[Articulo]]) -> 7790387001440 | Q32: =_xlfn.XLOOKUP(Tabla1[[#This Row],[Ean Normalizado]],tabla_consumos[EAN],tabla_consumos[Familia]) -> #N/A | R32: =_xlfn.XLOOKUP(Tabla1[[#This Row],[Ean Normalizado]],tabla_consumos[EAN],tabla_consumos[UM]) -> #N/A | S32: =Tabla1[[#This Row],[StockDisp]]*Tabla1[[#This Row],[UM producto]] -> #N/A
A33: 6 | B33: CDM03 - MORENO 3 | C33: SERVICIOS ATLANTICO SA | E33: 7790000000206 | F33: 2007166 | G33: BOLSA RESIDUO 60X9030MIC NEGRASX50U | H33: UNIDAD | I33: 92 | J33: 0 | K33: 0 | L33: 0 | M33: 0 | N33: 0 | O33: 92 | P33: =TRIM(Tabla1[[#This Row],[Articulo]]) -> 7790000000206 | Q33: =_xlfn.XLOOKUP(Tabla1[[#This Row],[Ean Normalizado]],tabla_consumos[EAN],tabla_consumos[Familia]) -> #N/A | R33: =_xlfn.XLOOKUP(Tabla1[[#This Row],[Ean Normalizado]],tabla_consumos[EAN],tabla_consumos[UM]) -> #N/A | S33: =Tabla1[[#This Row],[StockDisp]]*Tabla1[[#This Row],[UM producto]] -> #N/A
A34: 6 | B34: CDM03 - MORENO 3 | C34: SERVICIOS ATLANTICO SA | D34: LIMPIADOR DESINFECTANTE | E34: 7798332280100 | F34: 2007425 | G34: GL_CLEAN BY PEROXY 4UX5LT SPARTAN | H34: UNIDAD | I34: 6 | J34: 0 | K34: 0 | L34: 0 | M34: 0 | N34: 0 | O34: 6 | P34: =TRIM(Tabla1[[#This Row],[Articulo]]) -> 7798332280100 | Q34: =_xlfn.XLOOKUP(Tabla1[[#This Row],[Ean Normalizado]],tabla_consumos[EAN],tabla_consumos[Familia]) -> #N/A | R34: =_xlfn.XLOOKUP(Tabla1[[#This Row],[Ean Normalizado]],tabla_consumos[EAN],tabla_consumos[UM]) -> #N/A | S34: =Tabla1[[#This Row],[StockDisp]]*Tabla1[[#This Row],[UM producto]] -> #N/A
A35: 6 | B35: CDM03 - MORENO 3 | C35: SERVICIOS ATLANTICO SA | D35: PAÑO MICROFIBRA | E35: 7790000000460 | F35: 2007483 | G35: GL_PANO MICROF.MULT ROJO CLEANTEX | H35: PALLET | I35: 680 | J35: 0 | K35: 0 | L35: 0 | M35: 0 | N35: 0 | O35: 680 | P35: =TRIM(Tabla1[[#This Row],[Articulo]]) -> 7790000000460 | Q35: =_xlfn.XLOOKUP(Tabla1[[#This Row],[Ean Normalizado]],tabla_consumos[EAN],tabla_consumos[Familia]) -> #N/A | R35: =_xlfn.XLOOKUP(Tabla1[[#This Row],[Ean Normalizado]],tabla_consumos[EAN],tabla_consumos[UM]) -> #N/A | S35: =Tabla1[[#This Row],[StockDisp]]*Tabla1[[#This Row],[UM producto]] -> #N/A
A36: 6 | B36: CDM03 - MORENO 3 | C36: SERVICIOS ATLANTICO SA | D36: BARBIJO DESCARTABLE | E36: 7790000000195 | F36: 2007157 | G36: BARBIJOS TRICAPA PR MARCA PROP X50U | H36: UNIDAD | I36: 2 | J36: 0 | K36: 0 | L36: 0 | M36: 0 | N36: 0 | O36: 2 | P36: =TRIM(Tabla1[[#This Row],[Articulo]]) -> 7790000000195 | Q36: =_xlfn.XLOOKUP(Tabla1[[#This Row],[Ean Normalizado]],tabla_consumos[EAN],tabla_consumos[Familia]) -> BARBIJOS | R36: =_xlfn.XLOOKUP(Tabla1[[#This Row],[Ean Normalizado]],tabla_consumos[EAN],tabla_consumos[UM]) -> 50 | S36: =Tabla1[[#This Row],[StockDisp]]*Tabla1[[#This Row],[UM producto]] -> 100
A37: 5 | B37: CDM02 - MORENO 2 | C37: SERVICIOS ATLANTICO SA | D37: VINAGRE ALCOHOL | E37: 7792378001477 | F37: 4019917 | G37: VINAGRE ALCOHOL X5LT GUSTOSO | H37: UNIDAD | I37: 299 | J37: 0 | K37: 0 | L37: 0 | M37: 0 | N37: 0 | O37: 299 | P37: =TRIM(Tabla1[[#This Row],[Articulo]]) -> 7792378001477 | Q37: =_xlfn.XLOOKUP(Tabla1[[#This Row],[Ean Normalizado]],tabla_consumos[EAN],tabla_consumos[Familia]) -> #N/A | R37: =_xlfn.XLOOKUP(Tabla1[[#This Row],[Ean Normalizado]],tabla_consumos[EAN],tabla_consumos[UM]) -> #N/A | S37: =Tabla1[[#This Row],[StockDisp]]*Tabla1[[#This Row],[UM producto]] -> #N/A
A38: 6 | B38: CDM03 - MORENO 3 | C38: SERVICIOS ATLANTICO SA | D38: PAPEL HIGIENICO | E38: 7790250066163 | F38: 2007408 | G38: GL_PAPEL HIG DH 30MTX4U ELITE | H38: UNIDAD | I38: 93 | J38: 0 | K38: 0 | L38: 0 | M38: 0 | N38: 0 | O38: 93 | P38: =TRIM(Tabla1[[#This Row],[Articulo]]) -> 7790250066163 | Q38: =_xlfn.XLOOKUP(Tabla1[[#This Row],[Ean Normalizado]],tabla_consumos[EAN],tabla_consumos[Familia]) -> #N/A | R38: =_xlfn.XLOOKUP(Tabla1[[#This Row],[Ean Normalizado]],tabla_consumos[EAN],tabla_consumos[UM]) -> #N/A | S38: =Tabla1[[#This Row],[StockDisp]]*Tabla1[[#This Row],[UM producto]] -> #N/A
A39: 6 | B39: CDM03 - MORENO 3 | C39: SERVICIOS ATLANTICO SA | D39: LAVANDINA | E39: 7798188650508 | F39: 2006529 | G39: GL LAVANDINA BIO X5L THAMES | H39: UNIDAD | I39: 336 | J39: 0 | K39: 0 | L39: 0 | M39: 8 | N39: 0 | O39: 328 | P39: =TRIM(Tabla1[[#This Row],[Articulo]]) -> 7798188650508 | Q39: =_xlfn.XLOOKUP(Tabla1[[#This Row],[Ean Normalizado]],tabla_consumos[EAN],tabla_consumos[Familia]) -> #N/A | R39: =_xlfn.XLOOKUP(Tabla1[[#This Row],[Ean Normalizado]],tabla_consumos[EAN],tabla_consumos[UM]) -> #N/A | S39: =Tabla1[[#This Row],[StockDisp]]*Tabla1[[#This Row],[UM producto]] -> #N/A
A40: 1 | B40: CD MORENO | C40: SERVICIOS ATLANTICO SA | D40: CARNE ENTERA CONGELADA | E40: 7790000000622 | F40: 4007708 | G40: GL LOMO CONG ENV.AL VACIO XKG | H40: Kgs | I40: 21.15 | J40: 0 | K40: 0 | L40: 0 | M40: 0 | N40: 0 | O40: 21.15 | P40: =TRIM(Tabla1[[#This Row],[Articulo]]) -> 7790000000622 | Q40: =_xlfn.XLOOKUP(Tabla1[[#This Row],[Ean Normalizado]],tabla_consumos[EAN],tabla_consumos[Familia]) -> #N/A | R40: =_xlfn.XLOOKUP(Tabla1[[#This Row],[Ean Normalizado]],tabla_consumos[EAN],tabla_consumos[UM]) -> #N/A | S40: =Tabla1[[#This Row],[StockDisp]]*Tabla1[[#This Row],[UM producto]] -> #N/A
...

Sheet Necesidad por familia
A1: Familia | B1: UM ultima compra | C1: Stock | D1: Consumo | E1: Diferencia | F1: Cobertura | G1: Estado | H1: Ultima OC | I1: Proveedor
A2: GUANTE PROPILENO | B2: 100 | C2: =SUMIF(Tabla1[Familia],Tabla2[[#This Row],[Familia]],Tabla1[Total])/Tabla2[[#This Row],[UM ultima compra]] -> 149 | D2: =SUMIF(tabla_consumos[Familia],Tabla2[[#This Row],[Familia]],tabla_consumos[Consumo total])/Tabla2[[#This Row],[UM ultima compra]] -> 216 | E2: =Tabla2[[#This Row],[Stock]]-Tabla2[[#This Row],[Consumo]] -> -67 | F2: =IFERROR(Tabla2[[#This Row],[Stock]]/Tabla2[[#This Row],[Consumo]],"Sin consumo") -> 0.68981481 | H2: 4600122109 | I2: CLP
A3: INDIVIDUAL HOSPITAL BRITANICO | B3: 1000 | C3: =SUMIF(Tabla1[Familia],Tabla2[[#This Row],[Familia]],Tabla1[Total])/Tabla2[[#This Row],[UM ultima compra]] -> 40 | D3: 23 | E3: =Tabla2[[#This Row],[Stock]]-Tabla2[[#This Row],[Consumo]] -> 17 | F3: =IFERROR(Tabla2[[#This Row],[Stock]]/Tabla2[[#This Row],[Consumo]],"Sin consumo") -> 1.7391304 | I3: Druck
A4: BANDEJA 101 | B4: 100 | C4: =SUMIF(Tabla1[Familia],Tabla2[[#This Row],[Familia]],Tabla1[Total])/Tabla2[[#This Row],[UM ultima compra]] -> 1816 | D4: =SUMIF(tabla_consumos[Familia],Tabla2[[#This Row],[Familia]],tabla_consumos[Consumo total])/Tabla2[[#This Row],[UM ultima compra]] -> 1651 | E4: =Tabla2[[#This Row],[Stock]]-Tabla2[[#This Row],[Consumo]] -> 165 | F4: =IFERROR(Tabla2[[#This Row],[Stock]]/Tabla2[[#This Row],[Consumo]],"Sin consumo") -> 1.0999394 | I4: Pack Express
A5: INDIVIDUAL FINOCCHIETO | B5: 1000 | C5: =SUMIF(Tabla1[Familia],Tabla2[[#This Row],[Familia]],Tabla1[Total])/Tabla2[[#This Row],[UM ultima compra]] -> 50 | D5: 25 | E5: =Tabla2[[#This Row],[Stock]]-Tabla2[[#This Row],[Consumo]] -> 25 | F5: =IFERROR(Tabla2[[#This Row],[Stock]]/Tabla2[[#This Row],[Consumo]],"Sin consumo") -> 2 | I5: Druck
A6: INDIVIDUAL IAF | B6: 1000 | C6: =SUMIF(Tabla1[Familia],Tabla2[[#This Row],[Familia]],Tabla1[Total])/Tabla2[[#This Row],[UM ultima compra]] -> 50 | D6: 25 | E6: =Tabla2[[#This Row],[Stock]]-Tabla2[[#This Row],[Consumo]] -> 25 | F6: =IFERROR(Tabla2[[#This Row],[Stock]]/Tabla2[[#This Row],[Consumo]],"Sin consumo") -> 2 | I6: Druck
A7: INDIVIDUAL SWISS MEDICAL | B7: 1000 | C7: =SUMIF(Tabla1[Familia],Tabla2[[#This Row],[Familia]],Tabla1[Total])/Tabla2[[#This Row],[UM ultima compra]] -> 0 | D7: =SUMIF(tabla_consumos[Familia],Tabla2[[#This Row],[Familia]],tabla_consumos[Consumo total])/Tabla2[[#This Row],[UM ultima compra]] -> 42 | E7: =Tabla2[[#This Row],[Stock]]-Tabla2[[#This Row],[Consumo]] -> -42 | F7: =IFERROR(Tabla2[[#This Row],[Stock]]/Tabla2[[#This Row],[Consumo]],"Sin consumo") -> 0 | G7: Entrega directa en cliente | I7: Druck
A8: SERVILLETA C/ LOGO C. GOURMET 33X21.5 | B8: 1000 | C8: =SUMIF(Tabla1[Familia],Tabla2[[#This Row],[Familia]],Tabla1[Total])/Tabla2[[#This Row],[UM ultima compra]] -> 0 | D8: =SUMIF(tabla_consumos[Familia],Tabla2[[#This Row],[Familia]],tabla_consumos[Consumo total])/Tabla2[[#This Row],[UM ultima compra]] -> 35 | E8: =Tabla2[[#This Row],[Stock]]-Tabla2[[#This Row],[Consumo]] -> -35 | F8: =IFERROR(Tabla2[[#This Row],[Stock]]/Tabla2[[#This Row],[Consumo]],"Sin consumo") -> 0 | G8: Pendiente entrega lustramax
A9: AGITADORES | B9: 1000 | C9: =SUMIF(Tabla1[Familia],Tabla2[[#This Row],[Familia]],Tabla1[Total])/Tabla2[[#This Row],[UM ultima compra]] -> 445 | D9: =SUMIF(tabla_consumos[Familia],Tabla2[[#This Row],[Familia]],tabla_consumos[Consumo total])/Tabla2[[#This Row],[UM ultima compra]] -> 300 | E9: =Tabla2[[#This Row],[Stock]]-Tabla2[[#This Row],[Consumo]] -> 145 | F9: =IFERROR(Tabla2[[#This Row],[Stock]]/Tabla2[[#This Row],[Consumo]],"Sin consumo") -> 1.4833333 | H9: 4600122542 | I9: Pack Express
A10: SERVILLETA SWISS MEDICAL | B10: 1000 | C10: =SUMIF(Tabla1[Familia],Tabla2[[#This Row],[Familia]],Tabla1[Total])/Tabla2[[#This Row],[UM ultima compra]] -> 75.2 | D10: =SUMIF(tabla_consumos[Familia],Tabla2[[#This Row],[Familia]],tabla_consumos[Consumo total])/Tabla2[[#This Row],[UM ultima compra]] -> 16 | E10: =Tabla2[[#This Row],[Stock]]-Tabla2[[#This Row],[Consumo]] -> 59.2 | F10: =IFERROR(Tabla2[[#This Row],[Stock]]/Tabla2[[#This Row],[Consumo]],"Sin consumo") -> 4.7 | H10: 4600122094 | I10: DL CLEAN
A11: CUCHARA SUNDAE | B11: 1000 | C11: =SUMIF(Tabla1[Familia],Tabla2[[#This Row],[Familia]],Tabla1[Total])/Tabla2[[#This Row],[UM ultima compra]] -> 124 | D11: =SUMIF(tabla_consumos[Familia],Tabla2[[#This Row],[Familia]],tabla_consumos[Consumo total])/Tabla2[[#This Row],[UM ultima compra]] -> 161 | E11: =Tabla2[[#This Row],[Stock]]-Tabla2[[#This Row],[Consumo]] -> -37 | F11: =IFERROR(Tabla2[[#This Row],[Stock]]/Tabla2[[#This Row],[Consumo]],"Sin consumo") -> 0.77018634 | H11: 4600122237 | I11: Achaplast
A12: VASO TERMICO 180 | B12: 1000 | C12: =SUMIF(Tabla1[Familia],Tabla2[[#This Row],[Familia]],Tabla1[Total])/Tabla2[[#This Row],[UM ultima compra]] -> 62 | D12: =SUMIF(tabla_consumos[Familia],Tabla2[[#This Row],[Familia]],tabla_consumos[Consumo total])/Tabla2[[#This Row],[UM ultima compra]] -> 12 | E12: =Tabla2[[#This Row],[Stock]]-Tabla2[[#This Row],[Consumo]] -> 50 | F12: =IFERROR(Tabla2[[#This Row],[Stock]]/Tabla2[[#This Row],[Consumo]],"Sin consumo") -> 5.1666667
A13: FILM PVC 38 | B13: 1 | C13: =SUMIF(Tabla1[Familia],Tabla2[[#This Row],[Familia]],Tabla1[Total])/Tabla2[[#This Row],[UM ultima compra]] -> 0 | D13: =SUMIF(tabla_consumos[Familia],Tabla2[[#This Row],[Familia]],tabla_consumos[Consumo total])/Tabla2[[#This Row],[UM ultima compra]] -> 354 | E13: =Tabla2[[#This Row],[Stock]]-Tabla2[[#This Row],[Consumo]] -> -354 | F13: =IFERROR(Tabla2[[#This Row],[Stock]]/Tabla2[[#This Row],[Consumo]],"Sin consumo") -> 0 | G13: Remplazar film
A14: CUCHILLO | B14: 1000 | C14: =SUMIF(Tabla1[Familia],Tabla2[[#This Row],[Familia]],Tabla1[Total])/Tabla2[[#This Row],[UM ultima compra]] -> 251 | D14: =SUMIF(tabla_consumos[Familia],Tabla2[[#This Row],[Familia]],tabla_consumos[Consumo total])/Tabla2[[#This Row],[UM ultima compra]] -> 55 | E14: =Tabla2[[#This Row],[Stock]]-Tabla2[[#This Row],[Consumo]] -> 196 | F14: =IFERROR(Tabla2[[#This Row],[Stock]]/Tabla2[[#This Row],[Consumo]],"Sin consumo") -> 4.5636364 | H14: 4600122001 | I14: Achaplast
A15: SERVILLETA ELITE 30X30 | B15: 1000 | C15: =SUMIF(Tabla1[Familia],Tabla2[[#This Row],[Familia]],Tabla1[Total])/Tabla2[[#This Row],[UM ultima compra]] -> 0 | D15: =SUMIF(tabla_consumos[Familia],Tabla2[[#This Row],[Familia]],tabla_consumos[Consumo total])/Tabla2[[#This Row],[UM ultima compra]] -> 0 | E15: =Tabla2[[#This Row],[Stock]]-Tabla2[[#This Row],[Consumo]] -> 0 | F15: =IFERROR(Tabla2[[#This Row],[Stock]]/Tabla2[[#This Row],[Consumo]],"Sin consumo") -> Sin consumo
A16: BARBIJOS | B16: 50 | C16: =SUMIF(Tabla1[Familia],Tabla2[[#This Row],[Familia]],Tabla1[Total])/Tabla2[[#This Row],[UM ultima compra]] -> 610 | D16: =SUMIF(tabla_consumos[Familia],Tabla2[[#This Row],[Familia]],tabla_consumos[Consumo total])/Tabla2[[#This Row],[UM ultima compra]] -> 152 | E16: =Tabla2[[#This Row],[Stock]]-Tabla2[[#This Row],[Consumo]] -> 458 | F16: =IFERROR(Tabla2[[#This Row],[Stock]]/Tabla2[[#This Row],[Consumo]],"Sin consumo") -> 4.0131579 | H16: 4600122676 | I16: Mollon
A17: TAPA BOWL COMPOSTABLE 960CC | B17: 600 | C17: =SUMIF(Tabla1[Familia],Tabla2[[#This Row],[Familia]],Tabla1[Total])/Tabla2[[#This Row],[UM ultima compra]] -> 27 | D17: =SUMIF(tabla_consumos[Familia],Tabla2[[#This Row],[Familia]],tabla_consumos[Consumo total])/Tabla2[[#This Row],[UM ultima compra]] -> 12 | E17: =Tabla2[[#This Row],[Stock]]-Tabla2[[#This Row],[Consumo]] -> 15 | F17: =IFERROR(Tabla2[[#This Row],[Stock]]/Tabla2[[#This Row],[Consumo]],"Sin consumo") -> 2.25 | H17: 4600121603 | I17: Biopackaging
A18: SERVILLETA 30X30 | B18: 1000 | C18: =SUMIF(Tabla1[Familia],Tabla2[[#This Row],[Familia]],Tabla1[Total])/Tabla2[[#This Row],[UM ultima compra]] -> 369 | D18: =SUMIF(tabla_consumos[Familia],Tabla2[[#This Row],[Familia]],tabla_consumos[Consumo total])/Tabla2[[#This Row],[UM ultima compra]] -> 415 | E18: =Tabla2[[#This Row],[Stock]]-Tabla2[[#This Row],[Consumo]] -> -46 | F18: =IFERROR(Tabla2[[#This Row],[Stock]]/Tabla2[[#This Row],[Consumo]],"Sin consumo") -> 0.88915663 | H18: 4600121883 | I18: CLP
A19: VASO PLASTICO 300CC | B19: 100 | C19: =SUMIF(Tabla1[Familia],Tabla2[[#This Row],[Familia]],Tabla1[Total])/Tabla2[[#This Row],[UM ultima compra]] -> 417 | D19: =SUMIF(tabla_consumos[Familia],Tabla2[[#This Row],[Familia]],tabla_consumos[Consumo total])/Tabla2[[#This Row],[UM ultima compra]] -> 225 | E19: =Tabla2[[#This Row],[Stock]]-Tabla2[[#This Row],[Consumo]] -> 192 | F19: =IFERROR(Tabla2[[#This Row],[Stock]]/Tabla2[[#This Row],[Consumo]],"Sin consumo") -> 1.8533333 | H19: 4600122427 | I19: Papelera Colon
A20: BOWL COMPOSTABLE 960CC | B20: 600 | C20: =SUMIF(Tabla1[Familia],Tabla2[[#This Row],[Familia]],Tabla1[Total])/Tabla2[[#This Row],[UM ultima compra]] -> 0 | D20: =SUMIF(tabla_consumos[Familia],Tabla2[[#This Row],[Familia]],tabla_consumos[Consumo total])/Tabla2[[#This Row],[UM ultima compra]] -> 20 | E20: =Tabla2[[#This Row],[Stock]]-Tabla2[[#This Row],[Consumo]] -> -20 | F20: =IFERROR(Tabla2[[#This Row],[Stock]]/Tabla2[[#This Row],[Consumo]],"Sin consumo") -> 0 | G20: Pendiente turnado 28.04 | H20: 4200295502 | I20: Biopackaging
A21: ARRANQUE 50X70 | B21: 6 | C21: =SUMIF(Tabla1[Familia],Tabla2[[#This Row],[Familia]],Tabla1[Total])/Tabla2[[#This Row],[UM ultima compra]] -> 14 | D21: =SUMIF(tabla_consumos[Familia],Tabla2[[#This Row],[Familia]],tabla_consumos[Consumo total])/Tabla2[[#This Row],[UM ultima compra]] -> 35 | E21: =Tabla2[[#This Row],[Stock]]-Tabla2[[#This Row],[Consumo]] -> -21 | F21: =IFERROR(Tabla2[[#This Row],[Stock]]/Tabla2[[#This Row],[Consumo]],"Sin consumo") -> 0.4 | G21: Pendiente turnado 28.04 | H21: 4600122805 | I21: Polyfilm
A22: ESCARBADIENTE | B22: 500 | C22: =SUMIF(Tabla1[Familia],Tabla2[[#This Row],[Familia]],Tabla1[Total])/Tabla2[[#This Row],[UM ultima compra]] -> 2517 | D22: =SUMIF(tabla_consumos[Familia],Tabla2[[#This Row],[Familia]],tabla_consumos[Consumo total])/Tabla2[[#This Row],[UM ultima compra]] -> 885 | E22: =Tabla2[[#This Row],[Stock]]-Tabla2[[#This Row],[Consumo]] -> 1632 | F22: =IFERROR(Tabla2[[#This Row],[Stock]]/Tabla2[[#This Row],[Consumo]],"Sin consumo") -> 2.8440678 | H22: 4600122321 | I22: Food Packaging
A23: VASO TERMICO 240 | B23: 1000 | C23: =SUMIF(Tabla1[Familia],Tabla2[[#This Row],[Familia]],Tabla1[Total])/Tabla2[[#This Row],[UM ultima compra]] -> 187 | D23: =SUMIF(tabla_consumos[Familia],Tabla2[[#This Row],[Familia]],tabla_consumos[Consumo total])/Tabla2[[#This Row],[UM ultima compra]] -> 146 | E23: =Tabla2[[#This Row],[Stock]]-Tabla2[[#This Row],[Consumo]] -> 41 | F23: =IFERROR(Tabla2[[#This Row],[Stock]]/Tabla2[[#This Row],[Consumo]],"Sin consumo") -> 1.2808219 | H23: 4600122427 | I23: Papelera Colon
A24: ARRANQUE 15x20 | B24: 12 | C24: =SUMIF(Tabla1[Familia],Tabla2[[#This Row],[Familia]],Tabla1[Total])/Tabla2[[#This Row],[UM ultima compra]] -> 38 | D24: =SUMIF(tabla_consumos[Familia],Tabla2[[#This Row],[Familia]],tabla_consumos[Consumo total])/Tabla2[[#This Row],[UM ultima compra]] -> 17 | E24: =Tabla2[[#This Row],[Stock]]-Tabla2[[#This Row],[Consumo]] -> 21 | F24: =IFERROR(Tabla2[[#This Row],[Stock]]/Tabla2[[#This Row],[Consumo]],"Sin consumo") -> 2.2352941
A25: ROLLO ALUMINIO 40 | B25: 1 | C25: =SUMIF(Tabla1[Familia],Tabla2[[#This Row],[Familia]],Tabla1[Total])/Tabla2[[#This Row],[UM ultima compra]] -> 72 | D25: =SUMIF(tabla_consumos[Familia],Tabla2[[#This Row],[Familia]],tabla_consumos[Consumo total])/Tabla2[[#This Row],[UM ultima compra]] -> 100 | E25: =Tabla2[[#This Row],[Stock]]-Tabla2[[#This Row],[Consumo]] -> -28 | F25: =IFERROR(Tabla2[[#This Row],[Stock]]/Tabla2[[#This Row],[Consumo]],"Sin consumo") -> 0.72
A26: BANDEJA 103 | B26: 100 | C26: =SUMIF(Tabla1[Familia],Tabla2[[#This Row],[Familia]],Tabla1[Total])/Tabla2[[#This Row],[UM ultima compra]] -> 293 | D26: =SUMIF(tabla_consumos[Familia],Tabla2[[#This Row],[Familia]],tabla_consumos[Consumo total])/Tabla2[[#This Row],[UM ultima compra]] -> 234 | E26: =Tabla2[[#This Row],[Stock]]-Tabla2[[#This Row],[Consumo]] -> 59 | F26: =IFERROR(Tabla2[[#This Row],[Stock]]/Tabla2[[#This Row],[Consumo]],"Sin consumo") -> 1.2521368 | H26: 4600121818 | I26: Pranamar
A27: INDIVIDUAL CHEF GOURMET | B27: 1000 | C27: =SUMIF(Tabla1[Familia],Tabla2[[#This Row],[Familia]],Tabla1[Total])/Tabla2[[#This Row],[UM ultima compra]] -> 88 | D27: =SUMIF(tabla_consumos[Familia],Tabla2[[#This Row],[Familia]],tabla_consumos[Consumo total])/Tabla2[[#This Row],[UM ultima compra]] -> 204 | E27: =Tabla2[[#This Row],[Stock]]-Tabla2[[#This Row],[Consumo]] -> -116 | F27: =IFERROR(Tabla2[[#This Row],[Stock]]/Tabla2[[#This Row],[Consumo]],"Sin consumo") -> 0.43137255 | G27: Transferencia reclamada 28.04 | H27: 5501511547 | I27: Transfe moreno
A28: VASO TERMICO 300 | B28: 1000 | C28: =SUMIF(Tabla1[Familia],Tabla2[[#This Row],[Familia]],Tabla1[Total])/Tabla2[[#This Row],[UM ultima compra]] -> 2 | D28: 20 | E28: =Tabla2[[#This Row],[Stock]]-Tabla2[[#This Row],[Consumo]] -> -18 | F28: =IFERROR(Tabla2[[#This Row],[Stock]]/Tabla2[[#This Row],[Consumo]],"Sin consumo") -> 0.1 | G28: Pendiente turnado 28.04 | H28: 4600122806 | I28: Papelera Colon
A29: COFIAS | B29: 100 | C29: =SUMIF(Tabla1[Familia],Tabla2[[#This Row],[Familia]],Tabla1[Total])/Tabla2[[#This Row],[UM ultima compra]] -> 417 | D29: 400 | E29: =Tabla2[[#This Row],[Stock]]-Tabla2[[#This Row],[Consumo]] -> 17 | F29: =IFERROR(Tabla2[[#This Row],[Stock]]/Tabla2[[#This Row],[Consumo]],"Sin consumo") -> 1.0425 | H29: 4600122238 | I29: Mollon
A30: SERVILLETAS ELITE 21x11 | B30: 18000 | C30: =SUMIF(Tabla1[Familia],Tabla2[[#This Row],[Familia]],Tabla1[Total])/Tabla2[[#This Row],[UM ultima compra]] -> 107 | D30: =SUMIF(tabla_consumos[Familia],Tabla2[[#This Row],[Familia]],tabla_consumos[Consumo total])/Tabla2[[#This Row],[UM ultima compra]] -> 100 | E30: =Tabla2[[#This Row],[Stock]]-Tabla2[[#This Row],[Consumo]] -> 7 | F30: =IFERROR(Tabla2[[#This Row],[Stock]]/Tabla2[[#This Row],[Consumo]],"Sin consumo") -> 1.07 | H30: 4600121998 | I30: Feprol
A31: ARRANQUE 20x30 | B31: 12 | C31: =SUMIF(Tabla1[Familia],Tabla2[[#This Row],[Familia]],Tabla1[Total])/Tabla2[[#This Row],[UM ultima compra]] -> 61 | D31: =SUMIF(tabla_consumos[Familia],Tabla2[[#This Row],[Familia]],tabla_consumos[Consumo total])/Tabla2[[#This Row],[UM ultima compra]] -> 54 | E31: =Tabla2[[#This Row],[Stock]]-Tabla2[[#This Row],[Consumo]] -> 7 | F31: =IFERROR(Tabla2[[#This Row],[Stock]]/Tabla2[[#This Row],[Consumo]],"Sin consumo") -> 1.1296296
A32: INDIVIDIDUAL HEALTH | B32: 1000 | C32: =SUMIF(Tabla1[Familia],Tabla2[[#This Row],[Familia]],Tabla1[Total])/Tabla2[[#This Row],[UM ultima compra]] -> 86 | D32: =SUMIF(tabla_consumos[Familia],Tabla2[[#This Row],[Familia]],tabla_consumos[Consumo total])/Tabla2[[#This Row],[UM ultima compra]] -> 59 | E32: =Tabla2[[#This Row],[Stock]]-Tabla2[[#This Row],[Consumo]] -> 27 | F32: =IFERROR(Tabla2[[#This Row],[Stock]]/Tabla2[[#This Row],[Consumo]],"Sin consumo") -> 1.4576271 | H32: 5501506974
A33: TAPA 101 | B33: 100 | C33: =SUMIF(Tabla1[Familia],Tabla2[[#This Row],[Familia]],Tabla1[Total])/Tabla2[[#This Row],[UM ultima compra]] -> 117 | D33: =SUMIF(tabla_consumos[Familia],Tabla2[[#This Row],[Familia]],tabla_consumos[Consumo total])/Tabla2[[#This Row],[UM ultima compra]] -> 40 | E33: =Tabla2[[#This Row],[Stock]]-Tabla2[[#This Row],[Consumo]] -> 77 | F33: =IFERROR(Tabla2[[#This Row],[Stock]]/Tabla2[[#This Row],[Consumo]],"Sin consumo") -> 2.925
A34: GUANTE NITRILO M | B34: 100 | C34: =SUMIF(Tabla1[Familia],Tabla2[[#This Row],[Familia]],Tabla1[Total])/Tabla2[[#This Row],[UM ultima compra]] -> 1164 | D34: =SUMIF(tabla_consumos[Familia],Tabla2[[#This Row],[Familia]],tabla_consumos[Consumo total])/Tabla2[[#This Row],[UM ultima compra]] -> 387 | E34: =Tabla2[[#This Row],[Stock]]-Tabla2[[#This Row],[Consumo]] -> 777 | F34: =IFERROR(Tabla2[[#This Row],[Stock]]/Tabla2[[#This Row],[Consumo]],"Sin consumo") -> 3.0077519
A35: ARRANQUE 40x60 | B35: 12 | C35: =SUMIF(Tabla1[Familia],Tabla2[[#This Row],[Familia]],Tabla1[Total])/Tabla2[[#This Row],[UM ultima compra]] -> 141 | D35: =SUMIF(tabla_consumos[Familia],Tabla2[[#This Row],[Familia]],tabla_consumos[Consumo total])/Tabla2[[#This Row],[UM ultima compra]] -> 56 | E35: =Tabla2[[#This Row],[Stock]]-Tabla2[[#This Row],[Consumo]] -> 85 | F35: =IFERROR(Tabla2[[#This Row],[Stock]]/Tabla2[[#This Row],[Consumo]],"Sin consumo") -> 2.5178571
A36: ANTORCHITAS | B36: 24 | C36: =SUMIF(Tabla1[Familia],Tabla2[[#This Row],[Familia]],Tabla1[Total])/Tabla2[[#This Row],[UM ultima compra]] -> 0 | D36: 200 | E36: =Tabla2[[#This Row],[Stock]]-Tabla2[[#This Row],[Consumo]] -> -200 | F36: =IFERROR(Tabla2[[#This Row],[Stock]]/Tabla2[[#This Row],[Consumo]],"Sin consumo") -> 0 | G36: Ingresa miercoles 29.04 | H36: 4600122102 | I36: Feprol
A37: BOLSA CAMISETA 40X50 | B37: 50 | C37: =SUMIF(Tabla1[Familia],Tabla2[[#This Row],[Familia]],Tabla1[Total])/Tabla2[[#This Row],[UM ultima compra]] -> 2983.2 | D37: =SUMIF(tabla_consumos[Familia],Tabla2[[#This Row],[Familia]],tabla_consumos[Consumo total])/Tabla2[[#This Row],[UM ultima compra]] -> 961.2 | E37: =Tabla2[[#This Row],[Stock]]-Tabla2[[#This Row],[Consumo]] -> 2022 | F37: =IFERROR(Tabla2[[#This Row],[Stock]]/Tabla2[[#This Row],[Consumo]],"Sin consumo") -> 3.1036205
A38: GUANTE LATEX M | B38: 100 | C38: =SUMIF(Tabla1[Familia],Tabla2[[#This Row],[Familia]],Tabla1[Total])/Tabla2[[#This Row],[UM ultima compra]] -> 638 | D38: =SUMIF(tabla_consumos[Familia],Tabla2[[#This Row],[Familia]],tabla_consumos[Consumo total])/Tabla2[[#This Row],[UM ultima compra]] -> 899 | E38: =Tabla2[[#This Row],[Stock]]-Tabla2[[#This Row],[Consumo]] -> -261 | F38: =IFERROR(Tabla2[[#This Row],[Stock]]/Tabla2[[#This Row],[Consumo]],"Sin consumo") -> 0.70967742
A39: BANDEJA 105 | B39: 100 | C39: =SUMIF(Tabla1[Familia],Tabla2[[#This Row],[Familia]],Tabla1[Total])/Tabla2[[#This Row],[UM ultima compra]] -> 957 | D39: =SUMIF(tabla_consumos[Familia],Tabla2[[#This Row],[Familia]],tabla_consumos[Consumo total])/Tabla2[[#This Row],[UM ultima compra]] -> 550 | E39: =Tabla2[[#This Row],[Stock]]-Tabla2[[#This Row],[Consumo]] -> 407 | F39: =IFERROR(Tabla2[[#This Row],[Stock]]/Tabla2[[#This Row],[Consumo]],"Sin consumo") -> 1.74 | H39: 4200293178, 4600121740 | I39: Pranamar
A40: SERVILLETAS SWISS 18x18 | B40: 1000 | C40: =SUMIF(Tabla1[Familia],Tabla2[[#This Row],[Familia]],Tabla1[Total])/Tabla2[[#This Row],[UM ultima compra]] -> 94 | D40: =SUMIF(tabla_consumos[Familia],Tabla2[[#This Row],[Familia]],tabla_consumos[Consumo total])/Tabla2[[#This Row],[UM ultima compra]] -> 4 | E40: =Tabla2[[#This Row],[Stock]]-Tabla2[[#This Row],[Consumo]] -> 90 | F40: =IFERROR(Tabla2[[#This Row],[Stock]]/Tabla2[[#This Row],[Consumo]],"Sin consumo") -> 23.5
...
